Workbook

Sheet Salários
A1: m
B4: Colaborador | C4: Chave | D4: Data de pagameno | E4: Salário/ dia | F4: Dias trabalhados | G4: Salário mês | H4: Horas trabalhadas | I4: Valor por hora | J4: Extra trab | K4: Valor extra | L4: Sab/ Dom/ Feriado | M4: Adiantamento | N4: Falta/ Desc | O4: Valor do Pagamento | P4: Pix | Q4: Observação | R4: Coluna1
C5: =MONTH(D5)& "-" &YEAR(D5) -> 12-1899
B6: Anderson | C6: =MONTH(D6)& "-" &YEAR(D6) -> 9-2023 | D6: 45171 | E6: =(2000/30) -> 66.666667 | F6: 30 | G6: =(E6*F6) -> 2000 | H6: 250 | I6: 20 | J6: 22 | K6: 20 | L6: 4 | M6: 1300 | N6: 0 | O6: =(G6)+(H6*I6)+(J6*K6)+(L6*100)-(M6) -> 6540 | P6: 35991762704 | R6: OK
B7: Cleiton | C7: =MONTH(D7)& "-" &YEAR(D7) -> 9-2023 | D7: 45171 | E7: =(2000/30) -> 66.666667 | F7: 30 | G7: =(E7*F7) -> 2000 | H7: 212 | I7: 14 | J7: 3.2 | K7: 14 | L7: 0 | M7: 0 | N7: 0 | O7: =(G7)+(H7*I7)+(J7*K7)+(L7*100)-(M7) -> 5012.8 | P7: stlcleiton751@gmail.com | R7: OK
B8: caio | C8: =MONTH(D8)& "-" &YEAR(D8) -> 9-2023 | D8: 45174 | E8: 50 | F8: 30 | G8: =(E8*F8) -> 1500 | H8: 178.6 | I8: 10 | J8: 3.5 | K8: 10 | L8: 3.5 | M8: 0 | N8: 0 | O8: =(G8)+(H8*I8)+(J8*K8)+(L8*100)-(M8) -> 3671 | P8: 15175052675 | Q8: Filipe pagou | R8: OK
B9: Cristiano | C9: =MONTH(D9)& "-" &YEAR(D9) -> 9-2023 | D9: 45171 | E9: 120 | F9: 30 | G9: =(E9*F9) -> 3600 | H9: 0 | I9: 0 | J9: 0 | K9: 0 | L9: 0 | M9: 0 | N9: 0 | O9: =(G9)+(H9*I9)+(J9*K9)+(L9*100)-(M9) -> 3600 | P9: Ag 3180 - Cc: 58076 | R9: OK
B10: Silvinho | C10: =MONTH(D10)& "-" &YEAR(D10) -> 9-2023 | D10: 45175 | E10: 100 | F10: 30 | G10: =(E10*F10) -> 3000 | H10: 205.9 | I10: 10 | J10: 17.8 | K10: 10 | L10: 2 | M10: 0 | N10: 0 | O10: =(G10)+(H10*I10)+(J10*K10)+(L10*100)-(M10) -> 5437 | P10: 35998195061 | R10: OK
B11: Tamiro | C11: =MONTH(D11)& "-" &YEAR(D11) -> 9-2023 | D11: 45174 | E11: 200 | F11: 30 | G11: =(E11*F11) -> 6000 | H11: 231 | I11: 0 | J11: 0 | K11: 0 | L11: 0 | M11: 0 | N11: 0 | O11: =(G11)+(H11*I11)+(J11*K11)+(L11*100)-(M11) -> 6000 | P11: Cheque | R11: OK
B12: Graziele | C12: =MONTH(D12)& "-" &YEAR(D12) -> 9-2023 | D12: 45171 | E12: 69.6667 | F12: 30 | G12: =(E12*F12) -> 2090.001 | H12: 0 | I12: 0 | J12: 0 | K12: 0 | L12: 0 | M12: 0 | N12: 0 | O12: =(G12)+(H12*I12)+(J12*K12)+(L12*100)-(M12) -> 2090.001 | P12: 38974715821 | R12: OK
B13: Vinicius | C13: =MONTH(D13)& "-" &YEAR(D13) -> 9-2023 | D13: 45175 | E13: 175 | F13: 30 | G13: 5250 | H13: 0 | I13: 0 | J13: 0 | K13: 0 | L13: 0 | M13: 0 | N13: 0 | O13: =(G13)+(H13*I13)+(J13*K13)+(L13*100)-(M13) -> 5250 | R13: OK
B14: Guri | C14: =MONTH(D14)& "-" &YEAR(D14) -> 9-2023 | D14: 45175 | E14: 56.6 | F14: 30 | G14: 1700 | H14: 137.2 | I14: 8 | L14: 0.5 | M14: 180 | N14: 0 | O14: =(G14)+(H14*I14)+(J14*K14)+(L14*100)-(M14) -> 2667.6 | P14: 3597287575 | R14: OK
B15: Samuel | C15: =MONTH(D15)& "-" &YEAR(D15) -> 9-2023 | D15: 45175 | E15: =(2000/30) -> 66.666667 | F15: 30 | G15: =(E15*F15) -> 2000 | H15: 199.8 | I15: 2.5 | J15: 0 | K15: 0 | L15: 0 | M15: 0 | N15: 0 | O15: =(G15)+(H15*I15)+(J15*K15)+(L15*100)-(M15) -> 2499.5 | P15: 12931826642 | R15: OK
O16: =(G16)+(H16*I16)+(J16*K16)+(L16*100)-(M16) -> 0
B19: Anderson | C19: =MONTH(D19)& "-" &YEAR(D19) -> 10-2023 | D19: 45203 | E19: =(2000/30) -> 66.666667 | F19: =(30-'Salários'!$N19) -> 30 | G19: =(E19*F19) -> 2000 | H19: 125 | I19: 20 | J19: 1 | K19: 20 | L19: 6 | M19: 1300 | O19: =(G19)+(H19*I19)+(J19*K19)+(L19*100)-(M19) -> 3820 | P19: 35991762704 | R19: ok
B20: Mimi | C20: =MONTH(D20)& "-" &YEAR(D20) -> 10-2023 | D20: 45203 | E20: 110 | F20: 30 | G20: 3300 | O20: =(G20)+(H20*I20)+(J20*K20)+(L20*100)-(M20) -> 3300 | Q20: Recisão: R$ 6564,74 | R20: OK
B21: caio | C21: =MONTH(D21)& "-" &YEAR(D21) -> 10-2023 | D21: 45203 | E21: 50 | F21: =(30-'Salários'!$N21) -> 29 | G21: =(E21*F21) -> 1450 | H21: 203.1 | I21: 10 | J21: 6.3 | K21: 10 | L21: 100 | N21: 1 | O21: =(G21)+(H21*I21)+(J21*K21)+(L21)-(M21) -> 3644 | P21: 15175052675 | Q21: Faltou 09/09 | R21: ok
B22: Cristiano | C22: =MONTH(D22)& "-" &YEAR(D22) -> 10-2023 | D22: 45203 | E22: 120 | F22: 17 | G22: =(E22*F22) -> 2040 | H22: 1 | I22: 100 | O22: =(G22)+(H22*I22)+(J22*K22)+(L22*100)-(M22) -> 2140 | P22: Ag 3180 - Cc: 58076 | R22: OK
B23: Silvinho | C23: =MONTH(D23)& "-" &YEAR(D23) -> 10-2023 | D23: 45203 | E23: 100 | F23: =(30-'Salários'!$N23) -> 30 | G23: =(E23*F23) -> 3000 | H23: 238.1 | I23: 13 | J23: 20.2 | K23: 13 | L23: 1 | O23: =(G23)+(H23*I23)+(J23*K23)+(L23*100)-(M23) -> 6457.9 | P23: 35998195061 | R23: OK
B24: Tamiro | C24: =MONTH(D24)& "-" &YEAR(D24) -> 10-2023 | D24: 45203 | E24: 200 | F24: =(30-'Salários'!$N24) -> 30 | G24: =(E24*F24) -> 6000 | I24: 0 | O24: =(G24)+(H24*I24)+(J24*K24)+(L24*100)-(M24) -> 6000 | P24: Cheque | R24: OK
B25: Graziele | C25: =MONTH(D25)& "-" &YEAR(D25) -> 10-2023 | D25: 45203 | E25: 69.6667 | F25: =(30-'Salários'!$N25) -> 30 | G25: =(E25*F25) -> 2090.001 | H25: 1 | I25: 342.7 | O25: =(G25)+(H25*I25)+(J25*K25)+(L25*100)-(M25) -> 2432.701 | P25: 38974715821 | R25: OK
B26: Vinicius | C26: =MONTH(D26)& "-" &YEAR(D26) -> 10-2023 | D26: 45203 | E26: 175 | F26: =(30-'Salários'!$N26) -> 30 | G26: =(E26*F26) -> 5250 | I26: 0 | M26: 2000 | O26: =(G26)+(H26*I26)+(J26*K26)+(L26*100)-(M26) -> 3250
B27: Guri | C27: =MONTH(D27)& "-" &YEAR(D27) -> 10-2023 | D27: 45203 | E27: =(1700/30) -> 56.666667 | F27: =(30-'Salários'!$N27) -> 30 | G27: =(E27*F27) -> 1700 | H27: 202.3 | I27: 8 | L27: 1 | M27: 400 | O27: =(G27)+(H27*I27)+(J27*K27)+(L27*100)-(M27) -> 3018.4 | P27: 3597287575 | Q27: DESCONTADO 120,00/ OK | R27: 2898.4
B28: Samuel | C28: =MONTH(D28)& "-" &YEAR(D28) -> 10-2023 | D28: 45203 | E28: =(2000/30) -> 66.666667 | F28: =(30-'Salários'!$N28) -> 30 | G28: =(E28*F28) -> 2000 | H28: 155.1 | I28: 3 | M28: 150 | O28: =(G28)+(H28*I28)+(J28*K28)+(L28*100)-(M28) -> 2315.3 | P28: 12931826642 | R28: OK
C29: =MONTH(D29)& "-" &YEAR(D29) -> 12-1899 | G29: =(E29*F29) -> 0 | O29: =(G29)+(H29*I29)+(J29*K29)+(L29*100)-(M29) -> 0
C30: =MONTH(D30)& "-" &YEAR(D30) -> 12-1899 | G30: =(E30*F30) -> 0 | O30: =(G30)+(H30*I30)+(J30*K30)+(L30*100)-(M30) -> 0
C31: =MONTH(D31)& "-" &YEAR(D31) -> 12-1899 | G31: =(E31*F31) -> 0 | O31: =(G31)+(H31*I31)+(J31*K31)+(L31*100)-(M31) -> 0
B32: Anderson | C32: =MONTH(D32)& "-" &YEAR(D32) -> 11-2023 | D32: 45233 | E32: =(2000/30) -> 66.666667 | F32: =(30-'Salários'!$N32) -> 30 | G32: =(E32*F32) -> 2000 | H32: 186 | I32: 20 | J32: 6 | K32: 20 | L32: 5 | M32: 1200 | O32: =(G32)+(H32*I32)+(J32*K32)+(L32*100)-(M32) -> 5140 | P32: 35991762704 | Q32: Conferido ok
C33: =MONTH(D33)& "-" &YEAR(D33) -> 11-2023 | D33: 45234 | F33: =(30-'Salários'!$N33) -> 30 | O33: =(G33)+(H33*I33)+(J33*K33)+(L33*100)-(M33) -> 0
B34: caio | C34: =MONTH(D34)& "-" &YEAR(D34) -> 11-2023 | D34: 45235 | E34: 50 | F34: =(30-'Salários'!$N34) -> 30 | G34: =(E34*F34) -> 1500 | H34: 157 | I34: 10 | J34: 2.4 | K34: 3.33 | L34: 1 | M34: 200 | O34: =(G34)+(H34*I34)+(J34*K34)+(L34*100)-(M34) -> 2977.992 | P34: 15175052675 | Q34: Conferido, confirmar sabado
B35: Cristiano | C35: =MONTH(D35)& "-" &YEAR(D35) -> 11-2023 | D35: 45236 | E35: 120 | F35: 17 | G35: =(E35*F35) -> 2040 | H35: 1 | I35: 233.7 | O35: =(G35)+(H35*I35)+(J35*K35)+(L35*100)-(M35) -> 2273.7 | P35: Ag 3180 - Cc: 58076 | Q35: Conferido ok
B36: Silvinho | C36: =MONTH(D36)& "-" &YEAR(D36) -> 11-2023 | D36: 45237 | E36: 100 | F36: =(30-'Salários'!$N36) -> 30 | G36: =(E36*F36) -> 3000 | H36: 224.3 | I36: 13 | J36: 15.5 | K36: 13 | L36: 6 | O36: =(G36)+(H36*I36)+(J36*K36)+(L36*100)-(M36) -> 6717.4 | P36: 35998195061 | Q36: Conferido ok
B37: Tamiro | C37: =MONTH(D37)& "-" &YEAR(D37) -> 11-2023 | D37: 45238 | E37: 200 | F37: =(30-'Salários'!$N37) -> 30 | G37: =(E37*F37) -> 6000 | I37: 0 | O37: =(G37)+(H37*I37)+(J37*K37)+(L37*100)-(M37) -> 6000 | P37: Cheque
B38: Graziele | C38: =MONTH(D38)& "-" &YEAR(D38) -> 11-2023 | D38: 45239 | E38: 69.6667 | F38: =(30-'Salários'!$N38) -> 30 | G38: 2300 | O38: =(G38)+(H38*I38)+(J38*K38)+(L38*100)-(M38) -> 2300 | P38: 38974715821 | Q38: Conferido ok
B39: Vinicius | C39: =MONTH(D39)& "-" &YEAR(D39) -> 11-2023 | D39: 45240 | E39: 175 | F39: =(30-'Salários'!$N39) -> 30 | G39: =(E39*F39) -> 5250 | I39: 0 | O39: =(G39)+(H39*I39)+(J39*K39)+(L39*100)-(M39) -> 5250
B40: Guri | C40: =MONTH(D40)& "-" &YEAR(D40) -> 11-2023 | D40: 45241 | E40: =(2000/30) -> 66.666667 | F40: =(30-'Salários'!$N40) -> 30 | G40: =(E40*F40) -> 2000 | H40: 195 | I40: 8 | J40: 3.2 | M40: 350 | O40: =(G40)+(H40*I40)+(J40*K40)+(L40*100)-(M40) -> 3210 | P40: 3597287575
B41: Samuel | C41: =MONTH(D41)& "-" &YEAR(D41) -> 11-2023 | D41: 45242 | E41: =(2000/30) -> 66.666667 | F41: =(30-'Salários'!$N41) -> 30 | G41: 2000 | H41: 207.2 | I41: 3 | J41: 2.7 | M41: 380 | O41: =(G41)+(H41*I41)+(J41*K41)+(L41*100)-(M41) -> 2241.6 | P41: 12931826642
C42: =MONTH(D42)& "-" &YEAR(D42) -> 12-1899 | G42: =(E42*F42) -> 0 | O42: =(G42)+(H42*I42)+(J42*K42)+(L42*100)-(M42) -> 0
C43: =MONTH(D43)& "-" &YEAR(D43) -> 12-1899 | G43: =(E43*F43) -> 0 | O43: =(G43)+(H43*I43)+(J43*K43)+(L43*100)-(M43) -> 0
C44: =MONTH(D44)& "-" &YEAR(D44) -> 12-1899 | G44: =(E44*F44) -> 0 | O44: =(G44)+(H44*I44)+(J44*K44)+(L44*100)-(M44) -> 0
...

Sheet 220 nova Anderson 
B3: Dia | C3: Chave | D3: H inicial | E3: H final | F3: Hora/ Dia | G3: Extra | H3: Diesel
B4: 45231 | C4: =MONTH(B4)& "-" &YEAR(B4) -> 11-2023 | D4: 2425 | E4: 2428 | F4: ='220 nova Anderson '!$E4-'220 nova Anderson '!$D4 -> 3 | G4: ='220 nova Anderson '!$F4-10 -> -7 | H4: 400
B5: 45232 | C5: =MONTH(B5)& "-" &YEAR(B5) -> 11-2023 | D5: =E4 -> 2428 | E5: 2435 | F5: ='220 nova Anderson '!$E5-'220 nova Anderson '!$D5 -> 7 | G5: ='220 nova Anderson '!$F5-10 -> -3
B6: 45233 | C6: =MONTH(B6)& "-" &YEAR(B6) -> 11-2023 | D6: =E5 -> 2435 | E6: 2442 | F6: ='220 nova Anderson '!$E6-'220 nova Anderson '!$D6 -> 7 | G6: ='220 nova Anderson '!$F6-10 -> -3
B7: 45234 | C7: =MONTH(B7)& "-" &YEAR(B7) -> 11-2023 | F7: ='220 nova Anderson '!$E7-'220 nova Anderson '!$D7 -> 0 | G7: ='220 nova Anderson '!$F7-10 -> -10
B8: 45235 | C8: =MONTH(B8)& "-" &YEAR(B8) -> 11-2023 | D8: =E7 | F8: ='220 nova Anderson '!$E8-'220 nova Anderson '!$D8 -> 0 | G8: ='220 nova Anderson '!$F8-10 -> -10
B9: 45236 | C9: =MONTH(B9)& "-" &YEAR(B9) -> 11-2023 | D9: 2442 | E9: 2451 | F9: ='220 nova Anderson '!$E9-'220 nova Anderson '!$D9 -> 9 | G9: ='220 nova Anderson '!$F9-10 -> -1
B10: 45237 | C10: =MONTH(B10)& "-" &YEAR(B10) -> 11-2023 | D10: =E9 -> 2451 | E10: 2461 | F10: ='220 nova Anderson '!$E10-'220 nova Anderson '!$D10 -> 10 | G10: ='220 nova Anderson '!$F10-10 -> 0 | H10: 370
B11: 45238 | C11: =MONTH(B11)& "-" &YEAR(B11) -> 11-2023 | D11: =E10 -> 2461 | E11: 2470 | F11: ='220 nova Anderson '!$E11-'220 nova Anderson '!$D11 -> 9 | G11: ='220 nova Anderson '!$F11-10 -> -1
B12: 45239 | C12: =MONTH(B12)& "-" &YEAR(B12) -> 11-2023 | D12: =E11 -> 2470 | E12: 2479 | F12: ='220 nova Anderson '!$E12-'220 nova Anderson '!$D12 -> 9 | G12: ='220 nova Anderson '!$F12-10 -> -1
B13: 45240 | C13: =MONTH(B13)& "-" &YEAR(B13) -> 11-2023 | D13: =E12 -> 2479 | E13: 2482 | F13: ='220 nova Anderson '!$E13-'220 nova Anderson '!$D13 -> 3 | G13: ='220 nova Anderson '!$F13-10 -> -7 | H13: 319
B14: 45241 | C14: =MONTH(B14)& "-" &YEAR(B14) -> 11-2023 | D14: =E13 -> 2482 | E14: 2490 | F14: ='220 nova Anderson '!$E14-'220 nova Anderson '!$D14 -> 8 | G14: ='220 nova Anderson '!$F14-10 -> -2
B15: 45242 | C15: =MONTH(B15)& "-" &YEAR(B15) -> 11-2023 | F15: ='220 nova Anderson '!$E15-'220 nova Anderson '!$D15 -> 0 | G15: ='220 nova Anderson '!$F15-10 -> -10
B16: 45243 | C16: =MONTH(B16)& "-" &YEAR(B16) -> 11-2023 | D16: 2490 | E16: 2496.5 | F16: ='220 nova Anderson '!$E16-'220 nova Anderson '!$D16 -> 6.5 | G16: ='220 nova Anderson '!$F16-10 -> -3.5
B17: 45244 | C17: =MONTH(B17)& "-" &YEAR(B17) -> 11-2023 | D17: =E16 -> 2496.5 | E17: 2497 | F17: ='220 nova Anderson '!$E17-'220 nova Anderson '!$D17 -> 0.5 | G17: ='220 nova Anderson '!$F17-10 -> -9.5
B18: 45245 | C18: =MONTH(B18)& "-" &YEAR(B18) -> 11-2023 | D18: =E17 -> 2497 | E18: 2508 | F18: ='220 nova Anderson '!$E18-'220 nova Anderson '!$D18 -> 11 | G18: ='220 nova Anderson '!$F18-10 -> 1 | H18: 680
B19: 45246 | C19: =MONTH(B19)& "-" &YEAR(B19) -> 11-2023 | D19: =E18 -> 2508 | E19: 2519 | F19: ='220 nova Anderson '!$E19-'220 nova Anderson '!$D19 -> 11 | G19: ='220 nova Anderson '!$F19-10 -> 1
B20: 45247 | C20: =MONTH(B20)& "-" &YEAR(B20) -> 11-2023 | D20: =E19 -> 2519 | E20: 2530 | F20: ='220 nova Anderson '!$E20-'220 nova Anderson '!$D20 -> 11 | G20: ='220 nova Anderson '!$F20-10 -> 1
B21: 45248 | C21: =MONTH(B21)& "-" &YEAR(B21) -> 11-2023 | D21: =E20 -> 2530 | E21: 2536 | F21: ='220 nova Anderson '!$E21-'220 nova Anderson '!$D21 -> 6 | G21: ='220 nova Anderson '!$F21-10 -> -4 | H21: 225
B22: 45249 | C22: =MONTH(B22)& "-" &YEAR(B22) -> 11-2023 | F22: ='220 nova Anderson '!$E22-'220 nova Anderson '!$D22 -> 0 | G22: ='220 nova Anderson '!$F22-10 -> -10
B23: 45250 | C23: =MONTH(B23)& "-" &YEAR(B23) -> 11-2023 | D23: 2536 | E23: 2546 | F23: ='220 nova Anderson '!$E23-'220 nova Anderson '!$D23 -> 10 | G23: ='220 nova Anderson '!$F23-10 -> 0
B24: 45251 | C24: =MONTH(B24)& "-" &YEAR(B24) -> 11-2023 | D24: =E23 -> 2546 | E24: 2557 | F24: ='220 nova Anderson '!$E24-'220 nova Anderson '!$D24 -> 11 | G24: ='220 nova Anderson '!$F24-10 -> 1
B25: 45252 | C25: =MONTH(B25)& "-" &YEAR(B25) -> 11-2023 | D25: =E24 -> 2557 | E25: 2564 | F25: ='220 nova Anderson '!$E25-'220 nova Anderson '!$D25 -> 7 | G25: ='220 nova Anderson '!$F25-10 -> -3 | H25: 240
B26: 45253 | C26: =MONTH(B26)& "-" &YEAR(B26) -> 11-2023 | D26: =E25 -> 2564 | E26: 2573 | F26: ='220 nova Anderson '!$E26-'220 nova Anderson '!$D26 -> 9 | G26: ='220 nova Anderson '!$F26-10 -> -1 | H26: 235
B27: 45254 | C27: =MONTH(B27)& "-" &YEAR(B27) -> 11-2023 | D27: =E26 -> 2573 | E27: 2583 | F27: ='220 nova Anderson '!$E27-'220 nova Anderson '!$D27 -> 10 | G27: ='220 nova Anderson '!$F27-10 -> 0 | H27: 235
B28: 45255 | C28: =MONTH(B28)& "-" &YEAR(B28) -> 11-2023 | D28: =E27 -> 2583 | E28: 2593 | F28: ='220 nova Anderson '!$E28-'220 nova Anderson '!$D28 -> 10 | G28: ='220 nova Anderson '!$F28-10 -> 0 | H28: 235
B29: 45256 | C29: =MONTH(B29)& "-" &YEAR(B29) -> 11-2023 | F29: ='220 nova Anderson '!$E29-'220 nova Anderson '!$D29 -> 0 | G29: ='220 nova Anderson '!$F29-10 -> -10
B30: 45257 | C30: =MONTH(B30)& "-" &YEAR(B30) -> 11-2023 | D30: 2593 | E30: 2603 | F30: ='220 nova Anderson '!$E30-'220 nova Anderson '!$D30 -> 10 | G30: ='220 nova Anderson '!$F30-10 -> 0 | H30: 240
B31: 45258 | C31: =MONTH(B31)& "-" &YEAR(B31) -> 11-2023 | D31: =E30 -> 2603 | E31: 2614 | F31: ='220 nova Anderson '!$E31-'220 nova Anderson '!$D31 -> 11 | G31: ='220 nova Anderson '!$F31-10 -> 1 | H31: 170
B32: 45259 | C32: =MONTH(B32)& "-" &YEAR(B32) -> 11-2023 | D32: =E31 -> 2614 | E32: 2618 | F32: ='220 nova Anderson '!$E32-'220 nova Anderson '!$D32 -> 4 | G32: ='220 nova Anderson '!$F32-10 -> -6 | H32: 200
B33: 45260 | C33: =MONTH(B33)& "-" &YEAR(B33) -> 11-2023 | D33: =E32 -> 2618 | E33: 2627 | F33: ='220 nova Anderson '!$E33-'220 nova Anderson '!$D33 -> 9 | G33: ='220 nova Anderson '!$F33-10 -> -1
B34: 45261 | C34: =MONTH(B34)& "-" &YEAR(B34) -> 12-2023 | D34: 2627 | E34: 2634 | F34: ='220 nova Anderson '!$E34-'220 nova Anderson '!$D34 -> 7 | G34: ='220 nova Anderson '!$F34-10 -> -3
B35: 45262 | C35: =MONTH(B35)& "-" &YEAR(B35) -> 12-2023 | F35: ='220 nova Anderson '!$E35-'220 nova Anderson '!$D35 -> 0 | G35: ='220 nova Anderson '!$F35-10 -> -10
B36: 45263 | C36: =MONTH(B36)& "-" &YEAR(B36) -> 12-2023 | F36: ='220 nova Anderson '!$E36-'220 nova Anderson '!$D36 -> 0 | G36: ='220 nova Anderson '!$F36-10 -> -10
B37: 45264 | C37: =MONTH(B37)& "-" &YEAR(B37) -> 12-2023 | D37: 2634 | E37: 2644 | F37: ='220 nova Anderson '!$E37-'220 nova Anderson '!$D37 -> 10 | G37: ='220 nova Anderson '!$F37-10 -> 0 | H37: 225
B38: 45265 | C38: =MONTH(B38)& "-" &YEAR(B38) -> 12-2023 | D38: =E37 -> 2644 | E38: 2654 | F38: ='220 nova Anderson '!$E38-'220 nova Anderson '!$D38 -> 10 | G38: ='220 nova Anderson '!$F38-10 -> 0 | H38: 242
B39: 45266 | C39: =MONTH(B39)& "-" &YEAR(B39) -> 12-2023 | D39: =E38 -> 2654 | E39: 2664 | F39: ='220 nova Anderson '!$E39-'220 nova Anderson '!$D39 -> 10 | G39: ='220 nova Anderson '!$F39-10 -> 0 | H39: 242
B40: 45267 | C40: =MONTH(B40)& "-" &YEAR(B40) -> 12-2023 | D40: =E39 -> 2664 | E40: 2675 | F40: ='220 nova Anderson '!$E40-'220 nova Anderson '!$D40 -> 11 | G40: ='220 nova Anderson '!$F40-10 -> 1 | H40: 195
B41: 45268 | C41: =MONTH(B41)& "-" &YEAR(B41) -> 12-2023 | D41: =E40 -> 2675 | E41: 2685 | F41: ='220 nova Anderson '!$E41-'220 nova Anderson '!$D41 -> 10 | G41: ='220 nova Anderson '!$F41-10 -> 0 | H41: 190
B42: 45269 | C42: =MONTH(B42)& "-" &YEAR(B42) -> 12-2023 | F42: ='220 nova Anderson '!$E42-'220 nova Anderson '!$D42 -> 0 | G42: ='220 nova Anderson '!$F42-10 -> -10
...

Sheet 220 Antiga Silvinho 
B3: Dia | C3: Chave | D3: H inicial | E3: H final | F3: Hora/ Dia | G3: Extra | H3: Diesel
B4: 45231 | C4: =MONTH(B4)& "-" &YEAR(B4) -> 11-2023 | D4: 5494.3 | E4: 5500.5 | F4: ='220 Antiga Silvinho '!$E4-'220 Antiga Silvinho '!$D4 -> 6.2 | G4: ='220 Antiga Silvinho '!$F4-10 -> -3.8
B5: 45232 | C5: =MONTH(B5)& "-" &YEAR(B5) -> 11-2023 | D5: =E4 -> 5500.5 | E5: 5510.9 | F5: ='220 Antiga Silvinho '!$E5-'220 Antiga Silvinho '!$D5 -> 10.4 | G5: ='220 Antiga Silvinho '!$F5-10 -> 0.4 | H5: 440
B6: 45233 | C6: =MONTH(B6)& "-" &YEAR(B6) -> 11-2023 | D6: =E5 -> 5510.9 | E6: 5521.3 | F6: ='220 Antiga Silvinho '!$E6-'220 Antiga Silvinho '!$D6 -> 10.4 | G6: ='220 Antiga Silvinho '!$F6-10 -> 0.4
B7: 45234 | C7: =MONTH(B7)& "-" &YEAR(B7) -> 11-2023 | D7: =E6 -> 5521.3 | E7: 5523.7 | F7: ='220 Antiga Silvinho '!$E7-'220 Antiga Silvinho '!$D7 -> 2.4 | G7: ='220 Antiga Silvinho '!$F7-10 -> -7.6 | H7: 350
B8: 45235 | C8: =MONTH(B8)& "-" &YEAR(B8) -> 11-2023 | D8: =E7 -> 5523.7 | E8: 5527.5 | F8: ='220 Antiga Silvinho '!$E8-'220 Antiga Silvinho '!$D8 -> 3.8 | G8: ='220 Antiga Silvinho '!$F8-10 -> -6.2
B9: 45236 | C9: =MONTH(B9)& "-" &YEAR(B9) -> 11-2023 | D9: =E8 -> 5527.5 | E9: 5538.3 | F9: ='220 Antiga Silvinho '!$E9-'220 Antiga Silvinho '!$D9 -> 10.8 | G9: ='220 Antiga Silvinho '!$F9-10 -> 0.8
B10: 45237 | C10: =MONTH(B10)& "-" &YEAR(B10) -> 11-2023 | D10: =E9 -> 5538.3 | E10: 5549.6 | F10: ='220 Antiga Silvinho '!$E10-'220 Antiga Silvinho '!$D10 -> 11.3 | G10: ='220 Antiga Silvinho '!$F10-10 -> 1.3
B11: 45238 | C11: =MONTH(B11)& "-" &YEAR(B11) -> 11-2023 | D11: =E10 -> 5549.6 | E11: 5561.1 | F11: ='220 Antiga Silvinho '!$E11-'220 Antiga Silvinho '!$D11 -> 11.5 | G11: ='220 Antiga Silvinho '!$F11-10 -> 1.5 | H11: 540
B12: 45239 | C12: =MONTH(B12)& "-" &YEAR(B12) -> 11-2023 | D12: =E11 -> 5561.1 | E12: 5572.5 | F12: ='220 Antiga Silvinho '!$E12-'220 Antiga Silvinho '!$D12 -> 11.4 | G12: ='220 Antiga Silvinho '!$F12-10 -> 1.4
B13: 45240 | C13: =MONTH(B13)& "-" &YEAR(B13) -> 11-2023 | D13: =E12 -> 5572.5 | E13: 5578.2 | F13: ='220 Antiga Silvinho '!$E13-'220 Antiga Silvinho '!$D13 -> 5.7 | G13: ='220 Antiga Silvinho '!$F13-10 -> -4.3 | H13: 400
B14: 45241 | C14: =MONTH(B14)& "-" &YEAR(B14) -> 11-2023 | F14: ='220 Antiga Silvinho '!$E14-'220 Antiga Silvinho '!$D14 -> 0 | G14: ='220 Antiga Silvinho '!$F14-10 -> -10
B15: 45242 | C15: =MONTH(B15)& "-" &YEAR(B15) -> 11-2023 | D15: =E14 | F15: ='220 Antiga Silvinho '!$E15-'220 Antiga Silvinho '!$D15 -> 0 | G15: ='220 Antiga Silvinho '!$F15-10 -> -10
B16: 45243 | C16: =MONTH(B16)& "-" &YEAR(B16) -> 11-2023 | D16: 5578.2 | E16: 5583.8 | F16: ='220 Antiga Silvinho '!$E16-'220 Antiga Silvinho '!$D16 -> 5.6 | G16: ='220 Antiga Silvinho '!$F16-10 -> -4.4
B17: 45244 | C17: =MONTH(B17)& "-" &YEAR(B17) -> 11-2023 | D17: =E16 -> 5583.8 | E17: 5595.3 | F17: ='220 Antiga Silvinho '!$E17-'220 Antiga Silvinho '!$D17 -> 11.5 | G17: ='220 Antiga Silvinho '!$F17-10 -> 1.5 | H17: 440
B18: 45245 | C18: =MONTH(B18)& "-" &YEAR(B18) -> 11-2023 | D18: =E17 -> 5595.3 | E18: 5605.9 | F18: ='220 Antiga Silvinho '!$E18-'220 Antiga Silvinho '!$D18 -> 10.6 | G18: ='220 Antiga Silvinho '!$F18-10 -> 0.6
B19: 45246 | C19: =MONTH(B19)& "-" &YEAR(B19) -> 11-2023 | D19: =E18 -> 5605.9 | E19: 5617 | F19: ='220 Antiga Silvinho '!$E19-'220 Antiga Silvinho '!$D19 -> 11.1 | G19: ='220 Antiga Silvinho '!$F19-10 -> 1.1 | H19: 440
B20: 45247 | C20: =MONTH(B20)& "-" &YEAR(B20) -> 11-2023 | D20: =E19 -> 5617 | E20: 5628 | F20: ='220 Antiga Silvinho '!$E20-'220 Antiga Silvinho '!$D20 -> 11 | G20: ='220 Antiga Silvinho '!$F20-10 -> 1
B21: 45248 | C21: =MONTH(B21)& "-" &YEAR(B21) -> 11-2023 | D21: =E20 -> 5628 | E21: 5638.6 | F21: ='220 Antiga Silvinho '!$E21-'220 Antiga Silvinho '!$D21 -> 10.6 | G21: ='220 Antiga Silvinho '!$F21-10 -> 0.6 | H21: 220
B22: 45249 | C22: =MONTH(B22)& "-" &YEAR(B22) -> 11-2023 | F22: ='220 Antiga Silvinho '!$E22-'220 Antiga Silvinho '!$D22 -> 0 | G22: ='220 Antiga Silvinho '!$F22-10 -> -10
B23: 45250 | C23: =MONTH(B23)& "-" &YEAR(B23) -> 11-2023 | D23: 5638 | E23: 5647.5 | F23: ='220 Antiga Silvinho '!$E23-'220 Antiga Silvinho '!$D23 -> 9.5 | G23: ='220 Antiga Silvinho '!$F23-10 -> -0.5 | H23: 220
B24: 45251 | C24: =MONTH(B24)& "-" &YEAR(B24) -> 11-2023 | D24: =E23 -> 5647.5 | E24: 5659.5 | F24: ='220 Antiga Silvinho '!$E24-'220 Antiga Silvinho '!$D24 -> 12 | G24: ='220 Antiga Silvinho '!$F24-10 -> 2 | H24: 200
B25: 45252 | C25: =MONTH(B25)& "-" &YEAR(B25) -> 11-2023 | D25: =E24 -> 5659.5 | E25: 5671.8 | F25: ='220 Antiga Silvinho '!$E25-'220 Antiga Silvinho '!$D25 -> 12.3 | G25: ='220 Antiga Silvinho '!$F25-10 -> 2.3 | H25: 237
B26: 45253 | C26: =MONTH(B26)& "-" &YEAR(B26) -> 11-2023 | D26: =E25 -> 5671.8 | E26: 5683.6 | F26: ='220 Antiga Silvinho '!$E26-'220 Antiga Silvinho '!$D26 -> 11.8 | G26: ='220 Antiga Silvinho '!$F26-10 -> 1.8
B27: 45254 | C27: =MONTH(B27)& "-" &YEAR(B27) -> 11-2023 | D27: 5683.6 | E27: 5692.3 | F27: ='220 Antiga Silvinho '!$E27-'220 Antiga Silvinho '!$D27 -> 8.7 | G27: ='220 Antiga Silvinho '!$F27-10 -> -1.3
B28: 45255 | C28: =MONTH(B28)& "-" &YEAR(B28) -> 11-2023 | F28: ='220 Antiga Silvinho '!$E28-'220 Antiga Silvinho '!$D28 -> 0 | G28: ='220 Antiga Silvinho '!$F28-10 -> -10
B29: 45256 | C29: =MONTH(B29)& "-" &YEAR(B29) -> 11-2023 | D29: =E28 | F29: ='220 Antiga Silvinho '!$E29-'220 Antiga Silvinho '!$D29 -> 0 | G29: ='220 Antiga Silvinho '!$F29-10 -> -10
B30: 45257 | C30: =MONTH(B30)& "-" &YEAR(B30) -> 11-2023 | D30: 5692.3 | E30: 5701.4 | F30: ='220 Antiga Silvinho '!$E30-'220 Antiga Silvinho '!$D30 -> 9.1 | G30: ='220 Antiga Silvinho '!$F30-10 -> -0.9 | H30: 215
B31: 45258 | C31: =MONTH(B31)& "-" &YEAR(B31) -> 11-2023 | D31: =E30 -> 5701.4 | E31: 5704.8 | F31: ='220 Antiga Silvinho '!$E31-'220 Antiga Silvinho '!$D31 -> 3.4 | G31: ='220 Antiga Silvinho '!$F31-10 -> -6.6
B32: 45259 | C32: =MONTH(B32)& "-" &YEAR(B32) -> 11-2023 | F32: ='220 Antiga Silvinho '!$E32-'220 Antiga Silvinho '!$D32 -> 0 | G32: ='220 Antiga Silvinho '!$F32-10 -> -10
B33: 45260 | C33: =MONTH(B33)& "-" &YEAR(B33) -> 11-2023 | D33: 3651.6 | E33: 3660.9 | F33: ='220 Antiga Silvinho '!$E33-'220 Antiga Silvinho '!$D33 -> 9.3 | G33: ='220 Antiga Silvinho '!$F33-10 -> -0.7
B34: 45261 | C34: =MONTH(B34)& "-" &YEAR(B34) -> 12-2023 | D34: 5704.8 | E34: 5715.9 | F34: ='220 Antiga Silvinho '!$E34-'220 Antiga Silvinho '!$D34 -> 11.1 | G34: ='220 Antiga Silvinho '!$F34-10 -> 1.1
B35: 45262 | C35: =MONTH(B35)& "-" &YEAR(B35) -> 12-2023 | D35: =E34 -> 5715.9 | E35: 5726.9 | F35: ='220 Antiga Silvinho '!$E35-'220 Antiga Silvinho '!$D35 -> 11 | G35: ='220 Antiga Silvinho '!$F35-10 -> 1 | H35: 420
B36: 45263 | C36: =MONTH(B36)& "-" &YEAR(B36) -> 12-2023 | D36: =E35 -> 5726.9 | E36: 5739.9 | F36: ='220 Antiga Silvinho '!$E36-'220 Antiga Silvinho '!$D36 -> 13 | G36: ='220 Antiga Silvinho '!$F36-10 -> 3
B37: 45264 | C37: =MONTH(B37)& "-" &YEAR(B37) -> 12-2023 | D37: =E36 -> 5739.9 | E37: 5741.5 | F37: ='220 Antiga Silvinho '!$E37-'220 Antiga Silvinho '!$D37 -> 1.6 | G37: ='220 Antiga Silvinho '!$F37-10 -> -8.4
B38: 45265 | C38: =MONTH(B38)& "-" &YEAR(B38) -> 12-2023 | D38: =E37 -> 5741.5 | E38: 5747.2 | F38: ='220 Antiga Silvinho '!$E38-'220 Antiga Silvinho '!$D38 -> 5.7 | G38: ='220 Antiga Silvinho '!$F38-10 -> -4.3
B39: 45266 | C39: =MONTH(B39)& "-" &YEAR(B39) -> 12-2023 | D39: =E38 -> 5747.2 | E39: 5749.7 | F39: ='220 Antiga Silvinho '!$E39-'220 Antiga Silvinho '!$D39 -> 2.5 | G39: ='220 Antiga Silvinho '!$F39-10 -> -7.5
B40: 45267 | C40: =MONTH(B40)& "-" &YEAR(B40) -> 12-2023 | D40: =E39 -> 5749.7 | E40: 5759 | F40: ='220 Antiga Silvinho '!$E40-'220 Antiga Silvinho '!$D40 -> 9.3 | G40: ='220 Antiga Silvinho '!$F40-10 -> -0.7 | H40: 460
B41: 45268 | C41: =MONTH(B41)& "-" &YEAR(B41) -> 12-2023 | F41: ='220 Antiga Silvinho '!$E41-'220 Antiga Silvinho '!$D41 -> 0 | G41: ='220 Antiga Silvinho '!$F41-10 -> -10
B42: 45269 | C42: =MONTH(B42)& "-" &YEAR(B42) -> 12-2023 | D42: =E41 | F42: ='220 Antiga Silvinho '!$E42-'220 Antiga Silvinho '!$D42 -> 0 | G42: ='220 Antiga Silvinho '!$F42-10 -> -10
...

Sheet Sanny
B1: Escavadeira 210
B3: Data | C3: chave | D3: H incial | E3: H final | F3: Total | G3: Extra | H3: Colaborador | I3: Diesel
B4: 45231 | C4: =MONTH(B4)& "-" &YEAR(B4) -> 11-2023 | F4: =Sanny!$E4-Sanny!$D4 -> 0 | G4: =Sanny!$F4-10 -> -10 | H4: Manutenção
B5: 45232 | C5: =MONTH(B5)& "-" &YEAR(B5) -> 11-2023 | F5: =Sanny!$E5-Sanny!$D5 -> 0 | G5: =Sanny!$F5-10 -> -10 | H5: Manutenção
B6: 45233 | C6: =MONTH(B6)& "-" &YEAR(B6) -> 11-2023 | D6: 2065.9 | E6: 2074.2 | F6: =Sanny!$E6-Sanny!$D6 -> 8.3 | G6: =Sanny!$F6-10 -> -1.7 | H6: Reginaldo
B7: 45234 | C7: =MONTH(B7)& "-" &YEAR(B7) -> 11-2023 | D7: 2074.2 | E7: 2084.1 | F7: =Sanny!$E7-Sanny!$D7 -> 9.9 | G7: =Sanny!$F7-10 -> -0.1 | H7: Reginaldo
B8: 45235 | C8: =MONTH(B8)& "-" &YEAR(B8) -> 11-2023 | D8: 2084.1 | E8: 2091.3 | F8: =Sanny!$E8-Sanny!$D8 -> 7.2 | G8: =Sanny!$F8-10 -> -2.8 | H8: Silvinho
B9: 45236 | C9: =MONTH(B9)& "-" &YEAR(B9) -> 11-2023 | D9: 2091.3 | E9: 2094.2 | F9: =Sanny!$E9-Sanny!$D9 -> 2.9 | G9: =Sanny!$F9-10 -> -7.1 | H9: Rafael
B10: 45237 | C10: =MONTH(B10)& "-" &YEAR(B10) -> 11-2023 | D10: 2094.2 | E10: 2105.1 | F10: =Sanny!$E10-Sanny!$D10 -> 10.9 | G10: =Sanny!$F10-10 -> 0.9 | H10: Rafael
B11: 45238 | C11: =MONTH(B11)& "-" &YEAR(B11) -> 11-2023 | D11: 2105.1 | E11: 2113.4 | F11: =Sanny!$E11-Sanny!$D11 -> 8.3 | G11: =Sanny!$F11-10 -> -1.7 | H11: Rafael
B12: 45239 | C12: =MONTH(B12)& "-" &YEAR(B12) -> 11-2023 | D12: 2113.4 | E12: 2115.8 | F12: =Sanny!$E12-Sanny!$D12 -> 2.4 | G12: =Sanny!$F12-10 -> -7.6 | H12: Rafael
B13: 45240 | C13: =MONTH(B13)& "-" &YEAR(B13) -> 11-2023 | D13: 2115.8 | E13: 2125.1 | F13: =Sanny!$E13-Sanny!$D13 -> 9.3 | G13: =Sanny!$F13-10 -> -0.7 | H13: rafael
B14: 45241 | C14: =MONTH(B14)& "-" &YEAR(B14) -> 11-2023 | D14: 2125.1 | E14: 2132.4 | F14: =Sanny!$E14-Sanny!$D14 -> 7.3 | G14: =Sanny!$F14-10 -> -2.7 | H14: Rafael
B15: 45242 | C15: =MONTH(B15)& "-" &YEAR(B15) -> 11-2023 | F15: =Sanny!$E15-Sanny!$D15 -> 0 | G15: =Sanny!$F15-10 -> -10
B16: 45243 | C16: =MONTH(B16)& "-" &YEAR(B16) -> 11-2023 | F16: =Sanny!$E16-Sanny!$D16 -> 0 | G16: =Sanny!$F16-10 -> -10
B17: 45244 | C17: =MONTH(B17)& "-" &YEAR(B17) -> 11-2023 | D17: 2132.4 | E17: 2136.4 | F17: =Sanny!$E17-Sanny!$D17 -> 4 | G17: =Sanny!$F17-10 -> -6 | H17: Rafael
B18: 45245 | C18: =MONTH(B18)& "-" &YEAR(B18) -> 11-2023 | D18: 2136.4 | E18: 2143.5 | F18: =Sanny!$E18-Sanny!$D18 -> 7.1 | G18: =Sanny!$F18-10 -> -2.9 | H18: Rafael
B19: 45246 | C19: =MONTH(B19)& "-" &YEAR(B19) -> 11-2023 | D19: 2143.5 | E19: 2152.1 | F19: =Sanny!$E19-Sanny!$D19 -> 8.6 | G19: =Sanny!$F19-10 -> -1.4 | H19: Rafael
B20: 45247 | C20: =MONTH(B20)& "-" &YEAR(B20) -> 11-2023 | D20: 2152.1 | E20: 2161.3 | F20: =Sanny!$E20-Sanny!$D20 -> 9.2 | G20: =Sanny!$F20-10 -> -0.8 | H20: Rafael
B21: 45248 | C21: =MONTH(B21)& "-" &YEAR(B21) -> 11-2023 | F21: =E18-D18 -> 7.1 | G21: =F20-10 -> -0.8
B22: 45249 | C22: =MONTH(B22)& "-" &YEAR(B22) -> 11-2023 | F22: =E19-D19 -> 8.6 | G22: =F21-10 -> -2.9
B23: 45250 | C23: =MONTH(B23)& "-" &YEAR(B23) -> 11-2023 | F23: =E20-D20 -> 9.2 | G23: =F22-10 -> -1.4
B24: 45251 | C24: =MONTH(B24)& "-" &YEAR(B24) -> 11-2023 | F24: =E21-D21 -> 0 | G24: =F23-10 -> -0.8
B25: 45252 | C25: =MONTH(B25)& "-" &YEAR(B25) -> 11-2023 | F25: =E22-D22 -> 0 | G25: =F24-10 -> -10
B26: 45253 | C26: =MONTH(B26)& "-" &YEAR(B26) -> 11-2023 | F26: =E23-D23 -> 0 | G26: =F25-10 -> -10
B27: 45254 | C27: =MONTH(B27)& "-" &YEAR(B27) -> 11-2023 | F27: =E24-D24 -> 0 | G27: =F26-10 -> -10
B28: 45255 | C28: =MONTH(B28)& "-" &YEAR(B28) -> 11-2023 | F28: =E25-D25 -> 0 | G28: =F27-10 -> -10
B29: 45256 | C29: =MONTH(B29)& "-" &YEAR(B29) -> 11-2023 | F29: =E26-D26 -> 0 | G29: =F28-10 -> -10
B30: 45257 | C30: =MONTH(B30)& "-" &YEAR(B30) -> 11-2023 | F30: =E27-D27 -> 0 | G30: =F29-10 -> -10
B31: 45258 | C31: =MONTH(B31)& "-" &YEAR(B31) -> 11-2023 | F31: =E28-D28 -> 0 | G31: =F30-10 -> -10
B32: 45259 | C32: =MONTH(B32)& "-" &YEAR(B32) -> 11-2023 | F32: =E29-D29 -> 0 | G32: =F31-10 -> -10
... B36: 45263 | C36: =MONTH(B36)& "-" &YEAR(B36) -> 12-2023 | F36: =E33-D33 -> 0 | G36: =F35-10 -> -10
B37: 45264 | C37: =MONTH(B37)& "-" &YEAR(B37) -> 12-2023 | D37: 2226.3 | E37: 2235 | F37: =Sanny!$E37-Sanny!$D37 -> 8.7 | G37: =Sanny!$F37-10 -> -1.3 | H37: Wender | I37: 150
B38: 45265 | C38: =MONTH(B38)& "-" &YEAR(B38) -> 12-2023 | D38: =E37 -> 2235 | E38: 2245.2 | F38: =Sanny!$E38-Sanny!$D38 -> 10.2 | G38: =Sanny!$F38-10 -> 0.2 | H38: Wender
B39: 45266 | C39: =MONTH(B39)& "-" &YEAR(B39) -> 12-2023 | F39: =Sanny!$E39-Sanny!$D39 -> 0 | G39: =Sanny!$F39-10 -> -10
B40: 45267 | C40: =MONTH(B40)& "-" &YEAR(B40) -> 12-2023 | D40: =E39 | F40: =Sanny!$E40-Sanny!$D40 -> 0 | G40: =Sanny!$F40-10 -> -10
B41: 45268 | C41: =MONTH(B41)& "-" &YEAR(B41) -> 12-2023 | D41: =E40 | F41: =Sanny!$E41-Sanny!$D41 -> 0 | G41: =Sanny!$F41-10 -> -10
B42: 45269 | C42: =MONTH(B42)& "-" &YEAR(B42) -> 12-2023 | D42: =E41 | F42: =Sanny!$E42-Sanny!$D42 -> 0 | G42: =Sanny!$F42-10 -> -10
B43: 45270 | C43: =MONTH(B43)& "-" &YEAR(B43) -> 12-2023 | D43: =E42 | F43: =Sanny!$E43-Sanny!$D43 -> 0 | G43: =Sanny!$F43-10 -> -10
B44: 45271 | C44: =MONTH(B44)& "-" &YEAR(B44) -> 12-2023 | D44: 2245.2 | E44: 2251.1 | F44: =Sanny!$E44-Sanny!$D44 -> 5.9 | G44: =Sanny!$F44-10 -> -4.1 | H44: Wender
...

Sheet 700J nova 
B3: 45463 | C3: =MONTH(B3)& "-" &YEAR(B3) -> 6-2024 | D3: 72 | E3: 80.5 | F3: =E3-D3 -> 8.5 | G3: =F3-10 -> -1.5 | H3: Caio
B4: 45464 | C4: =MONTH(B4)& "-" &YEAR(B4) -> 6-2024 | D4: =E3 -> 80.5 | E4: 88.8 | F4: =E4-D4 -> 8.3 | G4: =F4-10 -> -1.7 | H4: Caio
B5: 45465 | C5: =MONTH(B5)& "-" &YEAR(B5) -> 6-2024 | D5: =E4 -> 88.8 | E5: 94 | F5: =E5-D5 -> 5.2 | G5: =F5-10 -> -4.8 | H5: Caio
B6: 45466 | C6: =MONTH(B6)& "-" &YEAR(B6) -> 6-2024 | F6: =E6-D6 -> 0 | G6: =F6-10 -> -10 | H6: Caio
B7: 45467 | C7: =MONTH(B7)& "-" &YEAR(B7) -> 6-2024 | D7: 94 | E7: 102 | F7: =E7-D7 -> 8 | G7: =F7-10 -> -2 | H7: Caio
B8: 45468 | C8: =MONTH(B8)& "-" &YEAR(B8) -> 6-2024 | D8: =E7 -> 102 | E8: 112 | F8: =E8-D8 -> 10 | G8: =F8-10 -> 0 | H8: Caio
B9: 45469 | C9: =MONTH(B9)& "-" &YEAR(B9) -> 6-2024 | D9: =E8 -> 112 | E9: 119.8 | F9: =E9-D9 -> 7.8 | G9: =F9-10 -> -2.2 | H9: Caio
B10: 45470 | C10: =MONTH(B10)& "-" &YEAR(B10) -> 6-2024 | F10: =E10-D10 -> 0 | G10: =F10-10 -> -10 | H10: Caio
B11: 45471 | C11: =MONTH(B11)& "-" &YEAR(B11) -> 6-2024 | D11: 119.8 | E11: 130 | F11: =E11-D11 -> 10.2 | G11: =F11-10 -> 0.2 | H11: Caio
B12: 45472 | C12: =MONTH(B12)& "-" &YEAR(B12) -> 6-2024 | D12: =E11 -> 130 | E12: 135.4 | F12: =E12-D12 -> 5.4 | G12: =F12-10 -> -4.6 | H12: Caio
B13: 45454 | C13: =MONTH(B13)& "-" &YEAR(B13) -> 6-2024 | F13: =E13-D13 -> 0 | G13: =F13-10 -> -10
B14: 45455 | C14: =MONTH(B14)& "-" &YEAR(B14) -> 6-2024 | F14: =E14-D13 -> 0 | G14: =F14-10 -> -10
B15: 45456 | C15: =MONTH(B15)& "-" &YEAR(B15) -> 6-2024 | F15: =E15-D15 -> 0 | G15: =F15-10 -> -10
B16: 45457 | C16: =MONTH(B16)& "-" &YEAR(B16) -> 6-2024 | F16: =E16-D16 -> 0 | G16: =F16-10 -> -10
B17: 45458 | C17: =MONTH(B17)& "-" &YEAR(B17) -> 6-2024 | F17: =E17-D17 -> 0 | G17: =F17-10 -> -10
B18: 45459 | C18: =MONTH(B18)& "-" &YEAR(B18) -> 6-2024 | F18: =E18-D18 -> 0 | G18: =F18-10 -> -10
B19: 45460 | C19: =MONTH(B19)& "-" &YEAR(B19) -> 6-2024 | F19: =E19-D19 -> 0 | G19: =F19-10 -> -10
B20: 45461 | C20: =MONTH(B20)& "-" &YEAR(B20) -> 6-2024 | F20: =E20-D20 -> 0 | G20: =F20-10 -> -10
B21: 45462 | C21: =MONTH(B21)& "-" &YEAR(B21) -> 6-2024 | F21: =E21-D21 -> 0 | G21: =F21-10 -> -10
B22: 45463 | C22: =MONTH(B22)& "-" &YEAR(B22) -> 6-2024 | D22: 72 | E22: 80.5 | F22: =E22-D22 -> 8.5 | G22: =F22-10 -> -1.5
B23: 45464 | C23: =MONTH(B23)& "-" &YEAR(B23) -> 6-2024 | D23: =E22 -> 80.5 | E23: 88.8 | F23: =E23-D23 -> 8.3 | G23: =F23-10 -> -1.7
B24: 45465 | C24: =MONTH(B24)& "-" &YEAR(B24) -> 6-2024 | D24: =E23 -> 88.8 | E24: 94 | F24: =E24-D24 -> 5.2 | G24: =F24-10 -> -4.8
B25: 45466 | C25: =MONTH(B25)& "-" &YEAR(B25) -> 6-2024 | F25: =E25-D25 -> 0 | G25: =F25-10 -> -10
B26: 45467 | C26: =MONTH(B26)& "-" &YEAR(B26) -> 6-2024 | D26: 94 | E26: 102 | F26: =E26-D26 -> 8 | G26: =F26-10 -> -2
B27: 45468 | C27: =MONTH(B27)& "-" &YEAR(B27) -> 6-2024 | D27: =E26 -> 102 | E27: 112 | F27: =E27-D27 -> 10 | G27: =F27-10 -> 0
B28: 45469 | C28: =MONTH(B28)& "-" &YEAR(B28) -> 6-2024 | D28: =E27 -> 112 | E28: 119.8 | F28: =E28-D28 -> 7.8 | G28: =F28-10 -> -2.2
B29: 45470 | C29: =MONTH(B29)& "-" &YEAR(B29) -> 6-2024 | F29: =E29-D29 -> 0 | G29: =F29-10 -> -10
B30: 45471 | C30: =MONTH(B30)& "-" &YEAR(B30) -> 6-2024 | D30: 119.8 | E30: 130 | F30: =E30-D30 -> 10.2 | G30: =F30-10 -> 0.2
B31: 45472 | C31: =MONTH(B31)& "-" &YEAR(B31) -> 6-2024 | D31: =E30 -> 130 | E31: 135.4 | F31: =E31-D31 -> 5.4 | G31: =F31-10 -> -4.6
B32: 45473 | C32: =MONTH(B32)& "-" &YEAR(B32) -> 6-2024 | F32: =E32-D32 -> 0 | G32: =F32-10 -> -10
B33: 45474 | C33: =MONTH(B33)& "-" &YEAR(B33) -> 7-2024 | D33: 135.4 | E33: 145.5 | F33: =E33-D33 -> 10.1 | G33: =F33-10 -> 0.1
B34: 45475 | C34: =MONTH(B34)& "-" &YEAR(B34) -> 7-2024 | D34: =E33 -> 145.5 | E34: 155.5 | F34: =E34-D34 -> 10 | G34: =F34-10 -> 0
B35: 45476 | C35: =MONTH(B35)& "-" &YEAR(B35) -> 7-2024 | D35: =E34 -> 155.5 | E35: 165.5 | F35: =E35-D35 -> 10 | G35: =F35-10 -> 0
B36: 45477 | C36: =MONTH(B36)& "-" &YEAR(B36) -> 7-2024 | D36: =E35 -> 165.5 | E36: 175.5 | F36: =E36-D36 -> 10 | G36: =F36-10 -> 0
B37: 45478 | C37: =MONTH(B37)& "-" &YEAR(B37) -> 7-2024 | D37: =E36 -> 175.5 | E37: 185.5 | F37: =E37-D37 -> 10 | G37: =F37-10 -> 0
B38: 45479 | C38: =MONTH(B38)& "-" &YEAR(B38) -> 7-2024 | F38: =E38-D38 -> 0 | G38: =F38-10 -> -10
B39: 45480 | C39: =MONTH(B39)& "-" &YEAR(B39) -> 7-2024 | D39: =E38 | F39: =E39-D39 -> 0 | G39: =F39-10 -> -10
B40: 45481 | C40: =MONTH(B40)& "-" &YEAR(B40) -> 7-2024 | D40: 185.5 | E40: 195.5 | F40: =E40-D40 -> 10 | G40: =F40-10 -> 0
B41: 45482 | C41: =MONTH(B41)& "-" &YEAR(B41) -> 7-2024 | D41: =E40 -> 195.5 | E41: 205.5 | F41: =E41-D41 -> 10 | G41: =F41-10 -> 0
B42: 45483 | C42: =MONTH(B42)& "-" &YEAR(B42) -> 7-2024 | D42: =E41 -> 205.5 | E42: 215.5 | F42: =E42-D42 -> 10 | G42: =F42-10 -> 0
...

Sheet 700J nova Armack 
B3: 45748 | C3: =MONTH(B3)& "-" &YEAR(B3) -> 4-2025 | D3: 1817.9 | E3: 1828.3 | F3: =E3-D3 -> 10.4 | G3: =F3-10 -> 0.4 | H3: 100 | I3: 7d2 | J3: Osmar
B4: 45749 | C4: =MONTH(B4)& "-" &YEAR(B4) -> 4-2025 | D4: =E3 -> 1828.3 | E4: 1839 | F4: =E4-D4 -> 10.7 | G4: =F4-10 -> 0.7 | H4: 230 | I4: 7d2 | J4: Osmar
B5: 45750 | C5: =MONTH(B5)& "-" &YEAR(B5) -> 4-2025 | D5: =E4 -> 1839 | E5: 1849.6 | F5: =E5-D5 -> 10.6 | G5: =F5-10 -> 0.6 | I5: 7d2 | J5: Osmar
B6: 45751 | C6: =MONTH(B6)& "-" &YEAR(B6) -> 4-2025 | D6: =E5 -> 1849.6 | E6: 1859.1 | F6: =E6-D6 -> 9.5 | G6: =F6-10 -> -0.5 | H6: 200 | I6: 7d2 | J6: Osmar
B7: 45752 | C7: =MONTH(B7)& "-" &YEAR(B7) -> 4-2025 | D7: =E6 -> 1859.1 | E7: 1866.9 | F7: =E7-D7 -> 7.8 | G7: =F7-10 -> -2.2 | I7: 7d2 | J7: Osmar
B8: 45753 | C8: =MONTH(B8)& "-" &YEAR(B8) -> 4-2025 | F8: =E8-D8 -> 0 | G8: =F8-10 -> -10 | I8: 7d2 | J8: Osmar
B9: 45754 | C9: =MONTH(B9)& "-" &YEAR(B9) -> 4-2025 | D9: 1866.9 | E9: 1879.4 | F9: =E9-D9 -> 12.5 | G9: =F9-10 -> 2.5 | H9: 200 | I9: 7d2 | J9: Osmar
B10: 45755 | C10: =MONTH(B10)& "-" &YEAR(B10) -> 4-2025 | D10: =E9 -> 1879.4 | E10: 1889.8 | F10: =E10-D10 -> 10.4 | G10: =F10-10 -> 0.4 | I10: 7d2 | J10: Osmar
B11: 45756 | C11: =MONTH(B11)& "-" &YEAR(B11) -> 4-2025 | D11: =E10 -> 1889.8 | E11: 1894.9 | F11: =E11-D11 -> 5.1 | G11: =F11-10 -> -4.9 | H11: 400 | I11: 7d2 | J11: Osmar
B12: 45756 | C12: =MONTH(B12)& "-" &YEAR(B12) -> 4-2025 | D12: 5769.4 | E12: 5775.2 | F12: =E12-D12 -> 5.8 | G12: =F12-10 -> -4.2 | I12: 700J armack nova | J12: Osmar
B13: 45757 | C13: =MONTH(B13)& "-" &YEAR(B13) -> 4-2025 | D13: =E12 -> 5775.2 | E13: 5785.6 | F13: =E13-D13 -> 10.4 | G13: =F13-10 -> 0.4 | I13: 700J armack nova | J13: Osmar
B14: 45758 | C14: =MONTH(B14)& "-" &YEAR(B14) -> 4-2025 | D14: =E13 -> 5785.6 | E14: 5796.1 | F14: =E14-D14 -> 10.5 | G14: =F14-10 -> 0.5 | I14: 700J armack nova | J14: Osmar
B15: 45759 | C15: =MONTH(B15)& "-" &YEAR(B15) -> 4-2025 | F15: =E15-D15 -> 0 | G15: =F15-10 -> -10 | I15: 700J armack nova | J15: Osmar
B16: 45760 | C16: =MONTH(B16)& "-" &YEAR(B16) -> 4-2025 | D16: =E15 | F16: =E16-D16 -> 0 | G16: =F16-10 -> -10 | I16: 700J armack nova | J16: Osmar
B17: 45761 | C17: =MONTH(B17)& "-" &YEAR(B17) -> 4-2025 | D17: 5796.1 | E17: 5807 | F17: =E17-D17 -> 10.9 | G17: =F17-10 -> 0.9 | H17: 200 | I17: 700J armack nova | J17: Osmar
B18: 45762 | C18: =MONTH(B18)& "-" &YEAR(B18) -> 4-2025 | D18: =E17 -> 5807 | E18: 5817.4 | F18: =E18-D18 -> 10.4 | G18: =F18-10 -> 0.4 | I18: 700J armack nova | J18: Osmar
B19: 45763 | C19: =MONTH(B19)& "-" &YEAR(B19) -> 4-2025 | F19: =E19-D19 -> 0 | G19: =F19-10 -> -10 | I19: 700J armack nova | J19: Osmar
B20: 45764 | C20: =MONTH(B20)& "-" &YEAR(B20) -> 4-2025 | D20: 5817.4 | E20: 5825.7 | F20: =E20-D20 -> 8.3 | G20: =F20-10 -> -1.7 | H20: 200 | I20: 700J armack nova | J20: Osmar
B21: 45765 | C21: =MONTH(B21)& "-" &YEAR(B21) -> 4-2025 | F21: =E21-D21 -> 0 | G21: =F21-10 -> -10 | I21: 700J armack nova | J21: Osmar
B22: 45766 | C22: =MONTH(B22)& "-" &YEAR(B22) -> 4-2025 | D22: =E21 | F22: =E22-D22 -> 0 | G22: =F22-10 -> -10 | I22: 700J armack nova | J22: Osmar
B23: 45767 | C23: =MONTH(B23)& "-" &YEAR(B23) -> 4-2025 | D23: =E22 | F23: =E23-D23 -> 0 | G23: =F23-10 -> -10 | I23: 700J armack nova | J23: Osmar
B24: 45768 | C24: =MONTH(B24)& "-" &YEAR(B24) -> 4-2025 | D24: 5825.7 | E24: 5837 | F24: =E24-D24 -> 11.3 | G24: =F24-10 -> 1.3 | I24: 700J armack nova | J24: Osmar
B25: 45769 | C25: =MONTH(B25)& "-" &YEAR(B25) -> 4-2025 | D25: =E24 -> 5837 | E25: 5847.5 | F25: =E25-D25 -> 10.5 | G25: =F25-10 -> 0.5 | H25: 203 | I25: 700J armack nova | J25: Osmar
B26: 45770 | C26: =MONTH(B26)& "-" &YEAR(B26) -> 4-2025 | D26: =E25 -> 5847.5 | E26: 5858 | F26: =E26-D26 -> 10.5 | G26: =F26-10 -> 0.5 | I26: 700J armack nova | J26: Osmar
B27: 45771 | C27: =MONTH(B27)& "-" &YEAR(B27) -> 4-2025 | D27: =E26 -> 5858 | E27: 5868.5 | F27: =E27-D27 -> 10.5 | G27: =F27-10 -> 0.5 | H27: 150 | I27: 700J armack nova | J27: Osmar
B28: 45772 | C28: =MONTH(B28)& "-" &YEAR(B28) -> 4-2025 | D28: =E27 -> 5868.5 | E28: 5879.2 | F28: =E28-D28 -> 10.7 | G28: =F28-10 -> 0.7 | H28: 230 | I28: 700J armack nova | J28: Osmar
B29: 45773 | C29: =MONTH(B29)& "-" &YEAR(B29) -> 4-2025 | D29: =E28 -> 5879.2 | E29: 5886.1 | F29: =E29-D29 -> 6.9 | G29: =F29-10 -> -3.1 | I29: 700J armack nova | J29: Osmar
B30: 45774 | C30: =MONTH(B30)& "-" &YEAR(B30) -> 4-2025 | F30: =E30-D30 -> 0 | G30: =F30-10 -> -10 | I30: 700J armack nova | J30: Osmar
B31: 45775 | C31: =MONTH(B31)& "-" &YEAR(B31) -> 4-2025 | D31: 5886.1 | E31: 5894.7 | F31: =E31-D31 -> 8.6 | G31: =F31-10 -> -1.4 | H31: 250 | I31: 700J armack nova | J31: Osmar
B32: 45776 | C32: =MONTH(B32)& "-" &YEAR(B32) -> 4-2025 | D32: =E31 -> 5894.7 | E32: 5905.2 | F32: =E32-D32 -> 10.5 | G32: =F32-10 -> 0.5 | I32: 700J armack nova | J32: Osmar
B33: 45777 | C33: =MONTH(B33)& "-" &YEAR(B33) -> 4-2025 | D33: =E32 -> 5905.2 | E33: 5917 | F33: =E33-D33 -> 11.8 | G33: =F33-10 -> 1.8 | I33: 700J armack nova | J33: Osmar
B34: 45778 | C34: =MONTH(B34)& "-" &YEAR(B34) -> 5-2025 | D34: 5917 | E34: 5925.8 | F34: =E34-D34 -> 8.8 | G34: =F34-10 -> -1.2
B35: 45779 | C35: =MONTH(B35)& "-" &YEAR(B35) -> 5-2025 | D35: =E34 -> 5925.8 | E35: 5937.5 | F35: =E35-D35 -> 11.7 | G35: =F35-10 -> 1.7
B36: 45780 | C36: =MONTH(B36)& "-" &YEAR(B36) -> 5-2025 | D36: =E35 -> 5937.5 | E36: 5944.3 | F36: =E36-D36 -> 6.8 | G36: =F36-10 -> -3.2
B37: 45781 | C37: =MONTH(B37)& "-" &YEAR(B37) -> 5-2025 | F37: =E37-D37 -> 0 | G37: =F37-10 -> -10
B38: 45782 | C38: =MONTH(B38)& "-" &YEAR(B38) -> 5-2025 | D38: 5944.3 | E38: 5952.1 | F38: =E38-D38 -> 7.8 | G38: =F38-10 -> -2.2
B39: 45783 | C39: =MONTH(B39)& "-" &YEAR(B39) -> 5-2025 | D39: =E38 -> 5952.1 | E39: 5962.8 | F39: =E39-D39 -> 10.7 | G39: =F39-10 -> 0.7
B40: 45784 | C40: =MONTH(B40)& "-" &YEAR(B40) -> 5-2025 | D40: =E39 -> 5962.8 | E40: 5974.1 | F40: =E40-D40 -> 11.3 | G40: =F40-10 -> 1.3
B41: 45785 | C41: =MONTH(B41)& "-" &YEAR(B41) -> 5-2025 | D41: =E40 -> 5974.1 | E41: 5981 | F41: =E41-D41 -> 6.9 | G41: =F41-10 -> -3.1
B42: 45786 | C42: =MONTH(B42)& "-" &YEAR(B42) -> 5-2025 | D42: =E41 -> 5981 | E42: 5992.3 | F42: =E42-D42 -> 11.3 | G42: =F42-10 -> 1.3
...

Sheet pá carregadeira 
B3: 45962 | C3: =MONTH(B3)& "-" &YEAR(B3) -> 11-2025 | F3: =E3-D3 -> 0 | G3: =F3-10 -> -10
B4: 45963 | C4: =MONTH(B4)& "-" &YEAR(B4) -> 11-2025 | F4: =E4-D4 -> 0 | G4: =F4-10 -> -10
B5: 45964 | C5: =MONTH(B5)& "-" &YEAR(B5) -> 11-2025 | F5: =E5-D5 -> 0 | G5: =F5-10 -> -10
B6: 45965 | C6: =MONTH(B6)& "-" &YEAR(B6) -> 11-2025 | F6: =E6-D6 -> 0 | G6: =F6-10 -> -10
B7: 45966 | C7: =MONTH(B7)& "-" &YEAR(B7) -> 11-2025 | F7: =E7-D7 -> 0 | G7: =F7-10 -> -10
B8: 45967 | C8: =MONTH(B8)& "-" &YEAR(B8) -> 11-2025 | F8: =E8-D8 -> 0 | G8: =F8-10 -> -10
B9: 45968 | C9: =MONTH(B9)& "-" &YEAR(B9) -> 11-2025 | F9: =E9-D9 -> 0 | G9: =F9-10 -> -10
B10: 45969 | C10: =MONTH(B10)& "-" &YEAR(B10) -> 11-2025 | F10: =E10-D10 -> 0 | G10: =F10-10 -> -10
B11: 45970 | C11: =MONTH(B11)& "-" &YEAR(B11) -> 11-2025 | F11: =E11-D11 -> 0 | G11: =F11-10 -> -10
B12: 45971 | C12: =MONTH(B12)& "-" &YEAR(B12) -> 11-2025 | D12: 13970 | E12: 13977 | F12: =E12-D12 -> 7 | G12: =F12-10 -> -3
B13: 45972 | C13: =MONTH(B13)& "-" &YEAR(B13) -> 11-2025 | D13: =E12 -> 13977 | E13: 13980 | F13: =E13-D13 -> 3 | G13: =F13-10 -> -7
B14: 45973 | C14: =MONTH(B14)& "-" &YEAR(B14) -> 11-2025 | F14: =E14-D14 -> 0 | G14: =F14-10 -> -10
B15: 45974 | C15: =MONTH(B15)& "-" &YEAR(B15) -> 11-2025 | D15: 13980 | E15: 13984 | F15: =E15-D15 -> 4 | G15: =F15-10 -> -6
B16: 45975 | C16: =MONTH(B16)& "-" &YEAR(B16) -> 11-2025 | D16: =E15 -> 13984 | E16: 13992.6 | F16: =E16-D16 -> 8.6 | G16: =F16-10 -> -1.4
B17: 45976 | C17: =MONTH(B17)& "-" &YEAR(B17) -> 11-2025 | F17: =E17-D17 -> 0 | G17: =F17-10 -> -10
B18: 45977 | C18: =MONTH(B18)& "-" &YEAR(B18) -> 11-2025 | D18: =E17 | F18: =E18-D18 -> 0 | G18: =F18-10 -> -10
B19: 45978 | C19: =MONTH(B19)& "-" &YEAR(B19) -> 11-2025 | D19: =E18 | F19: =E19-D19 -> 0 | G19: =F19-10 -> -10
B20: 45979 | C20: =MONTH(B20)& "-" &YEAR(B20) -> 11-2025 | D20: 13992.6 | E20: 13995.9 | F20: =E20-D20 -> 3.3 | G20: =F20-10 -> -6.7
B21: 45980 | C21: =MONTH(B21)& "-" &YEAR(B21) -> 11-2025 | D21: =E20 -> 13995.9 | E21: 14002.6 | F21: =E21-D21 -> 6.7 | G21: =F21-10 -> -3.3
B22: 45981 | C22: =MONTH(B22)& "-" &YEAR(B22) -> 11-2025 | D22: =E21 -> 14002.6 | E22: 14010.7 | F22: =E22-D22 -> 8.1 | G22: =F22-10 -> -1.9
B23: 45982 | C23: =MONTH(B23)& "-" &YEAR(B23) -> 11-2025 | D23: =E22 -> 14010.7 | E23: 14019.6 | F23: =E23-D23 -> 8.9 | G23: =F23-10 -> -1.1
B24: 45983 | C24: =MONTH(B24)& "-" &YEAR(B24) -> 11-2025 | F24: =E24-D24 -> 0 | G24: =F24-10 -> -10
B25: 45984 | C25: =MONTH(B25)& "-" &YEAR(B25) -> 11-2025 | D25: =E24 | F25: =E25-D25 -> 0 | G25: =F25-10 -> -10
B26: 45985 | C26: =MONTH(B26)& "-" &YEAR(B26) -> 11-2025 | D26: =E25 | F26: =E26-D26 -> 0 | G26: =F26-10 -> -10
B27: 45986 | C27: =MONTH(B27)& "-" &YEAR(B27) -> 11-2025 | D27: 14019.6 | E27: 14027.6 | F27: =E27-D27 -> 8 | G27: =F27-10 -> -2
B28: 45987 | C28: =MONTH(B28)& "-" &YEAR(B28) -> 11-2025 | D28: =E27 -> 14027.6 | E28: 14035.1 | F28: =E28-D28 -> 7.5 | G28: =F28-10 -> -2.5
B29: 45988 | C29: =MONTH(B29)& "-" &YEAR(B29) -> 11-2025 | D29: =E28 -> 14035.1 | E29: 14042.6 | F29: =E29-D29 -> 7.5 | G29: =F29-10 -> -2.5
B30: 45989 | C30: =MONTH(B30)& "-" &YEAR(B30) -> 11-2025 | D30: =E29 -> 14042.6 | E30: 14051.7 | F30: =E30-D30 -> 9.1 | G30: =F30-10 -> -0.9 | H30: 1436
B31: 45990 | C31: =MONTH(B31)& "-" &YEAR(B31) -> 11-2025 | F31: =E31-D31 -> 0 | G31: =F31-10 -> -10
B32: 45991 | C32: =MONTH(B32)& "-" &YEAR(B32) -> 11-2025 | D32: =E31 | F32: =E32-D32 -> 0 | G32: =F32-10 -> -10
B33: 45992 | C33: =MONTH(B33)& "-" &YEAR(B33) -> 12-2025 | D33: =E32 | F33: =E33-D33 -> 0 | G33: =F33-10 -> -10
B34: 45993 | C34: =MONTH(B34)& "-" &YEAR(B34) -> 12-2025 | D34: =E33 | F34: =E34-D34 -> 0 | G34: =F34-10 -> -10
B35: 45994 | C35: =MONTH(B35)& "-" &YEAR(B35) -> 12-2025 | D35: =E34 | F35: =E35-D35 -> 0 | G35: =F35-10 -> -10
B36: 45995 | C36: =MONTH(B36)& "-" &YEAR(B36) -> 12-2025 | D36: =E35 | F36: =E36-D36 -> 0 | G36: =F36-10 -> -10
B37: 45996 | C37: =MONTH(B37)& "-" &YEAR(B37) -> 12-2025 | D37: =E36 | F37: =E37-D37 -> 0 | G37: =F37-10 -> -10
B38: 45997 | C38: =MONTH(B38)& "-" &YEAR(B38) -> 12-2025 | D38: =E37 | F38: =E38-D38 -> 0 | G38: =F38-10 -> -10
B39: 45998 | C39: =MONTH(B39)& "-" &YEAR(B39) -> 12-2025 | D39: =E38 | F39: =E39-D39 -> 0 | G39: =F39-10 -> -10
B40: 45999 | C40: =MONTH(B40)& "-" &YEAR(B40) -> 12-2025 | D40: =E39 | F40: =E40-D40 -> 0 | G40: =F40-10 -> -10
B41: 46000 | C41: =MONTH(B41)& "-" &YEAR(B41) -> 12-2025 | D41: =E40 | F41: =E41-D41 -> 0 | G41: =F41-10 -> -10
B42: 46001 | C42: =MONTH(B42)& "-" &YEAR(B42) -> 12-2025 | D42: =E41 | F42: =E42-D42 -> 0 | G42: =F42-10 -> -10
...

Sheet Maq D51 - Caio
C2: =MONTH(B2)& "-" &YEAR(B2) -> 12-1899 | D2: 223.9 | E2: 234 | F2: =E2-D2 -> 10.1 | G2: =F2-10 -> 0.1
C3: =MONTH(B3)& "-" &YEAR(B3) -> 12-1899 | D3: =E2 -> 234 | E3: 239.9 | F3: =E3-D3 -> 5.9 | G3: =F3-10 -> -4.1
A4: 45903 | C4: =MONTH(B4)& "-" &YEAR(B4) -> 12-1899 | F4: =E4-D4 -> 0 | G4: =F4-10 -> -10
A5: 45904 | C5: =MONTH(B5)& "-" &YEAR(B5) -> 12-1899 | F5: =E5-D5 -> 0 | G5: =F5-10 -> -10
A6: 45905 | C6: =MONTH(B6)& "-" &YEAR(B6) -> 12-1899 | F6: =E6-D6 -> 0 | G6: =F6-10 -> -10
A7: 45906 | C7: =MONTH(B7)& "-" &YEAR(B7) -> 12-1899 | F7: =E7-D7 -> 0 | G7: =F7-10 -> -10
A8: 45907 | C8: =MONTH(B8)& "-" &YEAR(B8) -> 12-1899 | F8: =E8-D8 -> 0 | G8: =F8-10 -> -10
A9: 45908 | C9: =MONTH(B9)& "-" &YEAR(B9) -> 12-1899 | F9: =E9-D9 -> 0 | G9: =F9-10 -> -10
A10: 45909 | C10: =MONTH(B10)& "-" &YEAR(B10) -> 12-1899 | F10: =E10-D10 -> 0 | G10: =F10-10 -> -10
A11: 45910 | C11: =MONTH(B11)& "-" &YEAR(B11) -> 12-1899 | F11: =E11-D11 -> 0 | G11: =F11-10 -> -10
A12: 45911 | C12: =MONTH(B12)& "-" &YEAR(B12) -> 12-1899 | F12: =E12-D12 -> 0 | G12: =F12-10 -> -10
A13: 45912 | C13: =MONTH(B13)& "-" &YEAR(B13) -> 12-1899 | F13: =E13-D13 -> 0 | G13: =F13-10 -> -10
A14: 45913 | C14: =MONTH(B14)& "-" &YEAR(B14) -> 12-1899 | F14: =E14-D14 -> 0 | G14: =F14-10 -> -10
A15: 45914 | C15: =MONTH(B15)& "-" &YEAR(B15) -> 12-1899 | F15: =E15-D15 -> 0 | G15: =F15-10 -> -10
... A31: 45930 | C31: =MONTH(B31)& "-" &YEAR(B31) -> 12-1899 | F31: =E31-D31 -> 0 | G31: =F31-10 -> -10
C32: =MONTH(B32)& "-" &YEAR(B32) -> 12-1899 | F32: =E32-D32 -> 0 | G32: =F32-10 -> -10
C33: =MONTH(B33)& "-" &YEAR(B33) -> 12-1899 | F33: =E33-D33 -> 0 | G33: =F33-10 -> -10
C34: =MONTH(B34)& "-" &YEAR(B34) -> 12-1899 | F34: =E34-D34 -> 0 | G34: =F34-10 -> -10
C35: =MONTH(B35)& "-" &YEAR(B35) -> 12-1899 | D35: =E4 | F35: =E35-D35 -> 0 | G35: =F35-10 -> -10
C36: =MONTH(B36)& "-" &YEAR(B36) -> 12-1899 | D36: 239.9 | E36: 248.9 | F36: =E36-D36 -> 9 | G36: =F36-10 -> -1
C37: =MONTH(B37)& "-" &YEAR(B37) -> 12-1899 | D37: =E36 -> 248.9 | E37: 259.7 | F37: =E37-D37 -> 10.8 | G37: =F37-10 -> 0.8
C38: =MONTH(B38)& "-" &YEAR(B38) -> 12-1899 | D38: =E37 -> 259.7 | E38: 271 | F38: =E38-D38 -> 11.3 | G38: =F38-10 -> 1.3
C39: =MONTH(B39)& "-" &YEAR(B39) -> 12-1899 | D39: =E38 -> 271 | E39: 281.7 | F39: =E39-D39 -> 10.7 | G39: =F39-10 -> 0.7
C40: =MONTH(B40)& "-" &YEAR(B40) -> 12-1899 | D40: =E39 -> 281.7 | E40: 283.7 | F40: =E40-D40 -> 2 | G40: =F40-10 -> -8
C41: =MONTH(B41)& "-" &YEAR(B41) -> 12-1899 | F41: =E41-D41 -> 0 | G41: =F41-10 -> -10
C42: =MONTH(B42)& "-" &YEAR(B42) -> 12-1899 | D42: =E41 | F42: =E42-D42 -> 0 | G42: =F42-10 -> -10
C43: =MONTH(B43)& "-" &YEAR(B43) -> 12-1899 | D43: =E42 | F43: =E43-D43 -> 0 | G43: =F43-10 -> -10
C44: =MONTH(B44)& "-" &YEAR(B44) -> 12-1899 | D44: 283.7 | E44: 292.7 | F44: =E44-D44 -> 9 | G44: =F44-10 -> -1
C45: =MONTH(B45)& "-" &YEAR(B45) -> 12-1899 | D45: =E44 -> 292.7 | E45: 303.7 | F45: =E45-D45 -> 11 | G45: =F45-10 -> 1
C46: =MONTH(B46)& "-" &YEAR(B46) -> 12-1899 | D46: =E45 -> 303.7 | E46: 314 | F46: =E46-D46 -> 10.3 | G46: =F46-10 -> 0.3
C47: =MONTH(B47)& "-" &YEAR(B47) -> 12-1899 | D47: =E46 -> 314 | E47: 324 | F47: =E47-D47 -> 10 | G47: =F47-10 -> 0
C48: =MONTH(B48)& "-" &YEAR(B48) -> 12-1899 | D48: =E47 -> 324 | E48: 328.1 | F48: =E48-D48 -> 4.1 | G48: =F48-10 -> -5.9
C49: =MONTH(B49)& "-" &YEAR(B49) -> 12-1899 | F49: =E49-D49 -> 0 | G49: =F49-10 -> -10
C50: =MONTH(B50)& "-" &YEAR(B50) -> 12-1899 | D50: 328.1 | E50: 338.5 | F50: =E50-D50 -> 10.4 | G50: =F50-10 -> 0.4
C51: =MONTH(B51)& "-" &YEAR(B51) -> 12-1899 | D51: =E50 -> 338.5 | E51: 349 | F51: =E51-D51 -> 10.5 | G51: =F51-10 -> 0.5
C52: =MONTH(B52)& "-" &YEAR(B52) -> 12-1899 | D52: =E51 -> 349 | E52: 356.8 | F52: =E52-D52 -> 7.8 | G52: =F52-10 -> -2.2
C53: =MONTH(B53)& "-" &YEAR(B53) -> 12-1899 | D53: =E52 -> 356.8 | E53: 368.8 | F53: =E53-D53 -> 12 | G53: =F53-10 -> 2
C54: =MONTH(B54)& "-" &YEAR(B54) -> 12-1899 | D54: =E53 -> 368.8 | E54: 378 | F54: =E54-D54 -> 9.2 | G54: =F54-10 -> -0.8
C55: =MONTH(B55)& "-" &YEAR(B55) -> 12-1899 | F55: =E55-D55 -> 0 | G55: =F55-10 -> -10
C56: =MONTH(B56)& "-" &YEAR(B56) -> 12-1899 | D56: =E55 | F56: =E56-D56 -> 0 | G56: =F56-10 -> -10
...

Sheet D51 julio
B3: 45627 | C3: =MONTH(B3)& "-" &YEAR(B3) -> 12-2024 | D3: =E2 | F3: =E3-D3 -> 0 | G3: =F3-10 -> -10
B4: 45628 | C4: =MONTH(B4)& "-" &YEAR(B4) -> 12-2024 | D4: 2086 | E4: 2088.3 | F4: =E4-D4 -> 2.3 | G4: =F4-10 -> -7.7
B5: 45629 | C5: =MONTH(B5)& "-" &YEAR(B5) -> 12-2024 | F5: =E5-D5 -> 0 | G5: =F5-10 -> -10
B6: 45630 | C6: =MONTH(B6)& "-" &YEAR(B6) -> 12-2024 | D6: =E5 | F6: =E6-D6 -> 0 | G6: =F6-10 -> -10
B7: 45631 | C7: =MONTH(B7)& "-" &YEAR(B7) -> 12-2024 | D7: =E6 | F7: =E7-D7 -> 0 | G7: =F7-10 -> -10
B8: 45632 | C8: =MONTH(B8)& "-" &YEAR(B8) -> 12-2024 | D8: 2088.3 | E8: 2096.2 | F8: =E8-D8 -> 7.9 | G8: =F8-10 -> -2.1
B9: 45633 | C9: =MONTH(B9)& "-" &YEAR(B9) -> 12-2024 | D9: =E8 -> 2096.2 | E9: 2104.1 | F9: =E9-D9 -> 7.9 | G9: =F9-10 -> -2.1
B10: 45634 | C10: =MONTH(B10)& "-" &YEAR(B10) -> 12-2024 | D10: =E9 -> 2104.1 | E10: 2111 | F10: =E10-D10 -> 6.9 | G10: =F10-10 -> -3.1
B11: 45635 | C11: =MONTH(B11)& "-" &YEAR(B11) -> 12-2024 | D11: =E10 -> 2111 | E11: 2117 | F11: =E11-D11 -> 6 | G11: =F11-10 -> -4
B12: 45636 | C12: =MONTH(B12)& "-" &YEAR(B12) -> 12-2024 | D12: =E11 -> 2117 | E12: 2124.2 | F12: =E12-D12 -> 7.2 | G12: =F12-10 -> -2.8
B13: 45637 | C13: =MONTH(B13)& "-" &YEAR(B13) -> 12-2024 | D13: =E12 -> 2124.2 | E13: 2130 | F13: =E13-D13 -> 5.8 | G13: =F13-10 -> -4.2
B14: 45638 | C14: =MONTH(B14)& "-" &YEAR(B14) -> 12-2024 | D14: =E13 -> 2130 | E14: 2135.5 | F14: =E14-D14 -> 5.5 | G14: =F14-10 -> -4.5
B15: 45639 | C15: =MONTH(B15)& "-" &YEAR(B15) -> 12-2024 | D15: =E14 -> 2135.5 | E15: 2145.5 | F15: =E15-D15 -> 10 | G15: =F15-10 -> 0
B16: 45640 | C16: =MONTH(B16)& "-" &YEAR(B16) -> 12-2024 | F16: =E16-D16 -> 0 | G16: =F16-10 -> -10
B17: 45641 | C17: =MONTH(B17)& "-" &YEAR(B17) -> 12-2024 | D17: =E16 | F17: =E17-D17 -> 0 | G17: =F17-10 -> -10
B18: 45642 | C18: =MONTH(B18)& "-" &YEAR(B18) -> 12-2024 | D18: =E17 | F18: =E18-D18 -> 0 | G18: =F18-10 -> -10
B19: 45643 | C19: =MONTH(B19)& "-" &YEAR(B19) -> 12-2024 | D19: 2143.5 | E19: 2148.5 | F19: =E19-D19 -> 5 | G19: =F19-10 -> -5
B20: 45644 | C20: =MONTH(B20)& "-" &YEAR(B20) -> 12-2024 | D20: =E19 -> 2148.5 | E20: 2156.1 | F20: =E20-D20 -> 7.6 | G20: =F20-10 -> -2.4
B21: 45645 | C21: =MONTH(B21)& "-" &YEAR(B21) -> 12-2024 | D21: =E20 -> 2156.1 | E21: 2163.3 | F21: =E21-D21 -> 7.2 | G21: =F21-10 -> -2.8
B22: 45646 | C22: =MONTH(B22)& "-" &YEAR(B22) -> 12-2024 | D22: =E21 -> 2163.3 | E22: 2171.3 | F22: =E22-D22 -> 8 | G22: =F22-10 -> -2
B23: 45647 | C23: =MONTH(B23)& "-" &YEAR(B23) -> 12-2024 | F23: =E23-D23 -> 0 | G23: =F23-10 -> -10
B24: 45648 | C24: =MONTH(B24)& "-" &YEAR(B24) -> 12-2024 | D24: =E23 | F24: =E24-D24 -> 0 | G24: =F24-10 -> -10
B25: 45649 | C25: =MONTH(B25)& "-" &YEAR(B25) -> 12-2024 | D25: =E24 | F25: =E25-D25 -> 0 | G25: =F25-10 -> -10
B26: 45650 | C26: =MONTH(B26)& "-" &YEAR(B26) -> 12-2024 | D26: 2171.3 | E26: 2173 | F26: =E26-D26 -> 1.7 | G26: =F26-10 -> -8.3
B27: 45651 | C27: =MONTH(B27)& "-" &YEAR(B27) -> 12-2024 | F27: =E27-D27 -> 0 | G27: =F27-10 -> -10
B28: 45652 | C28: =MONTH(B28)& "-" &YEAR(B28) -> 12-2024 | D28: =E27 | F28: =E28-D28 -> 0 | G28: =F28-10 -> -10
B29: 45653 | C29: =MONTH(B29)& "-" &YEAR(B29) -> 12-2024 | D29: =E28 | F29: =E29-D29 -> 0 | G29: =F29-10 -> -10
B30: 45654 | C30: =MONTH(B30)& "-" &YEAR(B30) -> 12-2024 | D30: =E29 | F30: =E30-D30 -> 0 | G30: =F30-10 -> -10
B31: 45655 | C31: =MONTH(B31)& "-" &YEAR(B31) -> 12-2024 | D31: =E30 | F31: =E31-D31 -> 0 | G31: =F31-10 -> -10
B32: 45656 | C32: =MONTH(B32)& "-" &YEAR(B32) -> 12-2024 | D32: 2173 | E32: 2176 | F32: =E32-D32 -> 3 | G32: =F32-10 -> -7
B33: 45657 | C33: =MONTH(B33)& "-" &YEAR(B33) -> 12-2024 | F33: =E33-D33 -> 0 | G33: =F33-10 -> -10
B34: 45658 | C34: =MONTH(B34)& "-" &YEAR(B34) -> 1-2025 | F34: =E34-D34 -> 0 | G34: =F34-10 -> -10
B35: 45659 | C35: =MONTH(B35)& "-" &YEAR(B35) -> 1-2025 | D35: 2176 | E35: 2179.4 | F35: =E35-D35 -> 3.4 | G35: =F35-10 -> -6.6
B36: 45660 | C36: =MONTH(B36)& "-" &YEAR(B36) -> 1-2025 | F36: =E36-D36 -> 0 | G36: =F36-10 -> -10
B37: 45661 | C37: =MONTH(B37)& "-" &YEAR(B37) -> 1-2025 | F37: =E37-D37 -> 0 | G37: =F37-10 -> -10
B38: 45662 | C38: =MONTH(B38)& "-" &YEAR(B38) -> 1-2025 | F38: =E38-D38 -> 0 | G38: =F38-10 -> -10
B39: 45663 | C39: =MONTH(B39)& "-" &YEAR(B39) -> 1-2025 | F39: =E39-D39 -> 0 | G39: =F39-10 -> -10
B40: 45664 | C40: =MONTH(B40)& "-" &YEAR(B40) -> 1-2025 | D40: =E35 -> 2179.4 | E40: 2187.4 | F40: =E40-D40 -> 8 | G40: =F40-10 -> -2 | H40: 225 | I40: cliente
B41: 45665 | C41: =MONTH(B41)& "-" &YEAR(B41) -> 1-2025 | F41: =E41-D41 -> 0 | G41: =F41-10 -> -10
B42: 45666 | C42: =MONTH(B42)& "-" &YEAR(B42) -> 1-2025 | D42: =E41 | F42: =E42-D42 -> 0 | G42: =F42-10 -> -10
...

Sheet Caminhão 1513
B2: 45717 | C2: =MONTH(B2)& "-" &YEAR(B2) -> 3-2025 | D2: 0 | F2: =E2-D2 -> 0 | G2: =F2-10 -> -10
B3: 45718 | C3: =MONTH(B3)& "-" &YEAR(B3) -> 3-2025 | D3: =E2 | F3: =E3-D3 -> 0 | G3: =F3-10 -> -10
B4: 45748 | C4: =MONTH(B4)& "-" &YEAR(B4) -> 4-2025 | D4: =E3 | F4: =E4-D4 -> 0 | G4: =F4-10 -> -10
B5: 45749 | C5: =MONTH(B5)& "-" &YEAR(B5) -> 4-2025 | D5: =E4 | F5: =E5-D5 -> 0 | G5: =F5-10 -> -10
B6: 45750 | C6: =MONTH(B6)& "-" &YEAR(B6) -> 4-2025 | D6: =E5 | F6: =E6-D6 -> 0 | G6: =F6-10 -> -10
B7: 45751 | C7: =MONTH(B7)& "-" &YEAR(B7) -> 4-2025 | D7: =E6 | F7: =E7-D7 -> 0 | G7: =F7-10 -> -10
B8: 45752 | C8: =MONTH(B8)& "-" &YEAR(B8) -> 4-2025 | D8: 0.44444444 | E8: 0.75 | F8: =SUM(D8+E8) -> 1.1944444 | G8: =F8-10 -> -8.8055556
B9: 45753 | C9: =MONTH(B9)& "-" &YEAR(B9) -> 4-2025 | D9: 0.29166667 | E9: 0.75 | F9: =SUM(D9+E9) -> 1.0416667 | G9: =F9-10 -> -8.9583333
B10: 45754 | C10: =MONTH(B10)& "-" &YEAR(B10) -> 4-2025 | D10: 0.29166667 | E10: 0.5 | F10: =sum(E10+D10) -> 0.79166667 | G10: =F10-10 -> -9.2083333
B11: 45755 | C11: =MONTH(B11)& "-" &YEAR(B11) -> 4-2025 | D11: 0.29166667 | E11: 0.5 | F11: =sum(E11+D11) -> 0.79166667 | G11: =F11-10 -> -9.2083333
B12: 45756 | C12: =MONTH(B12)& "-" &YEAR(B12) -> 4-2025 | F12: =sum(E12+D12) -> 0 | G12: =F12-10 -> -10
B13: 45757 | C13: =MONTH(B13)& "-" &YEAR(B13) -> 4-2025 | D13: 0.58333333 | E13: 0.73333333 | F13: =sum(E13+D13) -> 1.3166667 | G13: =F13-10 -> -8.6833333
B14: 45758 | C14: =MONTH(B14)& "-" &YEAR(B14) -> 4-2025 | F14: =sum(E14+D14) -> 0 | G14: =F14-10 -> -10
B15: 45759 | C15: =MONTH(B15)& "-" &YEAR(B15) -> 4-2025 | D15: 0.29166667 | E15: 0.75 | F15: =sum(E15+D15) -> 1.0416667 | G15: =F15-10 -> -8.9583333
B16: 45760 | C16: =MONTH(B16)& "-" &YEAR(B16) -> 4-2025 | D16: 0.29166667 | E16: 0.75 | F16: =sum(E16+D16) -> 1.0416667 | G16: =F16-10 -> -8.9583333
B17: 45761 | C17: =MONTH(B17)& "-" &YEAR(B17) -> 4-2025 | D17: 0.29166667 | E17: 0.75 | F17: =sum(E17+D17) -> 1.0416667 | G17: =F17-10 -> -8.9583333
B18: 45762 | C18: =MONTH(B18)& "-" &YEAR(B18) -> 4-2025 | F18: =sum(E18+D18) -> 0 | G18: =F18-10 -> -10
B19: 45763 | C19: =MONTH(B19)& "-" &YEAR(B19) -> 4-2025 | D19: =E18 | F19: =sum(E19+D19) -> 0 | G19: =F19-10 -> -10
B20: 45764 | C20: =MONTH(B20)& "-" &YEAR(B20) -> 4-2025 | D20: =E19 | F20: =sum(E20+D20) -> 0 | G20: =F20-10 -> -10
B21: 45765 | C21: =MONTH(B21)& "-" &YEAR(B21) -> 4-2025 | D21: 0.29166667 | E21: 0.70833333 | F21: =sum(E21+D21) -> 1 | G21: =F21-10 -> -9
B22: 45766 | C22: =MONTH(B22)& "-" &YEAR(B22) -> 4-2025 | D22: 0.375 | E22: 0.72916667 | F22: =sum(E22+D22) -> 1.1041667 | G22: =F22-10 -> -8.8958333
B23: 45767 | C23: =MONTH(B23)& "-" &YEAR(B23) -> 4-2025 | D23: 0.29166667 | E23: 0.72916667 | F23: =sum(E23+D23) -> 1.0208333 | G23: =F23-10 -> -8.9791667
B24: 45768 | C24: =MONTH(B24)& "-" &YEAR(B24) -> 4-2025 | D24: 0.3125 | E24: 0.72916667 | F24: =sum(E24+D24) -> 1.0416667 | G24: =F24-10 -> -8.9583333
B25: 45769 | C25: =MONTH(B25)& "-" &YEAR(B25) -> 4-2025 | D25: =E24 -> 0.72916667 | F25: =sum(E25+D25) -> 0.72916667 | G25: =F25-10 -> -9.2708333
B26: 45770 | C26: =MONTH(B26)& "-" &YEAR(B26) -> 4-2025 | D26: =E25 | F26: =sum(E26+D26) -> 0 | G26: =F26-10 -> -10
B27: 45771 | C27: =MONTH(B27)& "-" &YEAR(B27) -> 4-2025 | D27: =E26 | F27: =sum(E27+D27) -> 0 | G27: =F27-10 -> -10
B28: 45772 | C28: =MONTH(B28)& "-" &YEAR(B28) -> 4-2025 | D28: =E27 | F28: =sum(E28+D28) -> 0 | G28: =F28-10 -> -10
B29: 45773 | C29: =MONTH(B29)& "-" &YEAR(B29) -> 4-2025 | D29: =E28 | F29: =sum(E29+D29) -> 0 | G29: =F29-10 -> -10
B30: 45774 | C30: =MONTH(B30)& "-" &YEAR(B30) -> 4-2025 | D30: =E29 | F30: =sum(E30+D30) -> 0 | G30: =F30-10 -> -10
B31: 45775 | C31: =MONTH(B31)& "-" &YEAR(B31) -> 4-2025 | D31: =E30 | F31: =sum(E31+D31) -> 0 | G31: =F31-10 -> -10
B32: 45776 | C32: =MONTH(B32)& "-" &YEAR(B32) -> 4-2025 | D32: 0.29166667 | E32: 0.72916667 | F32: =sum(E32+D32) -> 1.0208333 | G32: =F32-10 -> -8.9791667
B33: 45777 | C33: =MONTH(B33)& "-" &YEAR(B33) -> 4-2025 | F33: =sum(E33+D33) -> 0 | G33: =F33-10 -> -10
B34: 45778 | C34: =MONTH(B34)& "-" &YEAR(B34) -> 5-2025 | D34: =E33 | F34: =sum(E34+D34) -> 0 | G34: =F34-10 -> -10
B35: 45779 | C35: =MONTH(B35)& "-" &YEAR(B35) -> 5-2025 | D35: =E34 | F35: =sum(E35+D35) -> 0 | G35: =F35-10 -> -10
B36: 45780 | C36: =MONTH(B36)& "-" &YEAR(B36) -> 5-2025 | D36: =E35 | F36: =sum(E36+D36) -> 0 | G36: =F36-10 -> -10
D37: =E36 | F37: =sum(E37+D37) -> 0
D38: =E37 | F38: =sum(E38+D38) -> 0
D39: =E38 | F39: =sum(E39+D39) -> 0
D40: =E39 | F40: =sum(E40+D40) -> 0
D41: =E40 | F41: =sum(E41+D41) -> 0
...

Sheet 7D1
B3: Dia | C3: Chave | D3: H inicial | E3: H final | F3: Hora/ Dia | G3: Extra | H3: Colaborador | I3: Diesel
B4: 45231 | C4: =MONTH(B4)& "-" &YEAR(B4) -> 11-2023 | D4: 7306.9 | E4: 7314.3 | F4: ='7D1'!$E4-'7D1'!$D4 -> 7.4 | G4: ='7D1'!$F4-10 -> -2.6 | H4: Guri
B5: 45231 | C5: =MONTH(B5)& "-" &YEAR(B5) -> 11-2023 | D5: =E4 -> 7314.3 | E5: 7315.5 | F5: ='7D1'!$E5-'7D1'!$D5 -> 1.2 | G5: ='7D1'!$F5-10 -> -8.8 | H5: Guri | I5: 180
B6: 45232 | C6: =MONTH(B6)& "-" &YEAR(B6) -> 11-2023 | D6: =E5 -> 7315.5 | E6: 7323.7 | F6: ='7D1'!$E6-'7D1'!$D6 -> 8.2 | G6: ='7D1'!$F6-10 -> -1.8 | H6: Guri
B7: 45233 | C7: =MONTH(B7)& "-" &YEAR(B7) -> 11-2023 | D7: 7323.7 | E7: 7333.2 | F7: ='7D1'!$E7-'7D1'!$D7 -> 9.5 | G7: ='7D1'!$F7-10 -> -0.5 | H7: Guri | I7: 100
B8: 45234 | C8: =MONTH(B8)& "-" &YEAR(B8) -> 11-2023 | D8: 7333.2 | E8: 7334 | F8: ='7D1'!$E8-'7D1'!$D8 -> 0.8 | G8: ='7D1'!$F8-10 -> -9.2 | H8: Guri
